Workbook

Sheet MF 190(DTF101A)
A2: NAMA BARANG : MF 190 (DTF101A)
A4: TGL | B4: NAMA PT-PROYEK | C4: MASUK | D4: KELUAR | E4: SISA | F4: KETERANGAN
B5: SISA STOK 2017 | E5: 10569
A6: 43132 | B6: NINDYA KARYA-SDN 04 MERUYA 38+4 | C6: 42 | E6: =E5+C6-D6 -> 10611
A7: 43132 | B7: ACSET-MCC | C7: 13 | E7: =E6+C7-D7 -> 10624
A8: 43132 | B8: GLOBAL-AROSA | C8: 3 | E8: =E7+C8-D8 -> 10627
A9: 43132 | B9: GLOBAL-AROSA | C9: 66 | E9: =E8+C9-D9 -> 10693
A10: 43132 | B10: TBP-LAVIE | C10: 82 | E10: =E9+C10-D10 -> 10775
A11: 43132 | B11: TBP-JO.JIEXPO | C11: 220 | E11: =E10+C11-D11 -> 10995
A12: 43160 | B12: INDONAKANO-PANASONIC GOBEL | C12: 151 | E12: =E11+C12-D12 -> 11146
A13: 43160 | B13: BHINEKA-AHM | C13: 295 | E13: =E12+C13-D13 -> 11441 | F13: COCOK
A14: 43191 | B14: BHINEKA-AHM | C14: 83 | E14: =E13+C14-D14 -> 11524
A15: 43191 | B15: GLOBAL-AROSA | C15: 22 | E15: =E14+C15-D15 -> 11546
A16: 43191 | B16: TBP-LAVIE | C16: 73 | E16: =E15+C16-D16 -> 11619
A17: 43191 | B17: TBP-BBSI.JO | C17: 82 | E17: =E16+C17-D17 -> 11701 | F17: COCOK
A18: 43221 | B18: TBP-LAVIE | C18: 55 | E18: =E17+C18-D18 -> 11756
A19: 43221 | B19: NINDYA KARYA-RS.HARKIT | C19: 99 | E19: =E18+C19-D19 -> 11855
A20: 43221 | B20: NINDYA KARYA-SDN 04 MERUYA | C20: 17 | E20: =E19+C20-D20 -> 11872
A21: 43221 | B21: BHINEKA-AHM | C21: 56 | E21: =E20+C21-D21 -> 11928
A22: 43221 | B22: INDONAKANO-PANASONIC GOBEL | C22: 55 | E22: =E21+C22-D22 -> 11983 | F22: COCOK
A23: 43252 | B23: TOTAL-BBSI.JO | C23: 82 | E23: =E22+C23-D23 -> 12065
A24: 43252 | B24: ACSET-MCC | C24: 100 | E24: =E23+C24-D24 -> 12165
A25: 43252 | B25: NINDYA KARYA-HARAPAN KITA | C25: 59 | E25: =E24+C25-D25 -> 12224
A26: 43282 | B26: WIKA-TRANS CIBUBUR | D26: 320 | E26: =E25+C26-D26 -> 11904
A27: 43313 | B27: NINDYA LTM KSO-PUSK.CILILITAN | C27: 35 | E27: =E26+C27-D27 -> 11939
A28: 43313 | B28: WIKA-TRANS CIBUBUR | D28: 410 | E28: =E27+C28-D28 -> 11529 | F28: COCOK
A29: 43313 | B29: INDONAKANO-THAI SUMMIT | C29: 80 | E29: =E28+C29-D29 -> 11609
A30: 43313 | B30: ACSET-VISTA | C30: 90 | E30: =E29+C30-D30 -> 11699
A31: 43344 | B31: TOTAL-BBSI.JO | C31: 83 | E31: =E30+C31-D31 -> 11782 | F31: COCOK
A32: 43374 | B32: ACSET-MCC | C32: 45 | E32: =E31+C32-D32 -> 11827
A33: 43374 | B33: NINDYA KARYA-SDN 04 MERUYA | C33: 7 | E33: =E32+C33-D33 -> 11834
A34: 43374 | B34: WIKA-TRANS CIBUBUR | D34: 300 | E34: =E33+C34-D34 -> 11534 | F34: COCOK
A35: 43405 | B35: TOTAL-BBSI.JO | C35: 83 | E35: =E34+C35-D35 -> 11617
A36: 43405 | B36: NINDYA KARYA-SDN KEB.JERUK 06 | C36: 13 | E36: =E35+C36-D36 -> 11630
A37: 43405 | B37: WIKA-TRANS CIBUBUR | D37: 400 | E37: =E36+C37-D37 -> 11230
A38: 43435 | B38: NINDYA KARYA-HARAPAN KITA | C38: 86 | E38: =E37+C38-D38 -> 11316
A39: 43435 | B39: WIKA-TRANS CIBUBUR 100+380 | D39: 480 | E39: =E38+C39-D39 -> 10836 | F39: COCOK
A40: 13/1/2018 | B40: ACSET-MCC | C40: 40 | E40: =E39+C40-D40 -> 10876
A41: 13/1/2018 | B41: BHINEKA CP-AHM | C41: 3 | E41: =E40+C41-D41 -> 10879
A42: 13/1/2018 | B42: TBP-LAVIE | C42: 19 | E42: =E41+C42-D42 -> 10898
...

Sheet MF170(DTF101)
A2: NAMA BARANG : MF 170 (DTF101)
A4: TGL | B4: NAMA PT-PROYEK | C4: MASUK | D4: KELUAR | E4: SISA | F4: KETERANGAN
B5: STOK ALAT 2017 | E5: 8697
A6: 43132 | B6: NINDYA KARYA-SDN 04 MERUYA 42+5 | C6: 47 | E6: =E5+C6-D6 -> 8744
A7: 43132 | B7: ACSET-MCC | C7: 7 | E7: =E6+C7-D7 -> 8751
A8: 43132 | B8: GLOBAL-AROSA | C8: 2 | E8: =E7+C8-D8 -> 8753
A9: 43132 | B9: GLOBAL-AROSA | C9: 27 | E9: =E8+C9-D9 -> 8780
A10: 43160 | B10: BHINEKA-AHM 15+200 | C10: 215 | E10: =E9+C10-D10 -> 8995
A11: 43160 | B11: IDEA MANDIRI | C11: 100 | E11: =E10+C11-D11 -> 9095 | F11: COCOK
A12: 43191 | B12: TBP-LAVIE | C12: 1 | E12: =E11+C12-D12 -> 9096
A13: 43221 | B13: NINDYA KARYA-RS.HARKIT | C13: 121 | E13: =E12+C13-D13 -> 9217
A14: 43221 | B14: NINDYA.LTM KSO-PUSK.CEGER | C14: 58 | E14: =E13+C14-D14 -> 9275
A15: 43221 | B15: NINDYA KARYA-SDN 04 MERUYA | C15: 19 | E15: =E14+C15-D15 -> 9294
A16: 43221 | B16: BHINEKA-AHM | C16: 91 | E16: =E15+C16-D16 -> 9385
A17: 42856 | B17: INDONAKANO-GOBEL | C17: 50 | E17: =E16+C17-D17 -> 9435 | F17: COCOK
A18: 43252 | B18: NINDYA KARYA-HARAPAN KITA | C18: 107 | E18: =E17+C18-D18 -> 9542
A19: 43252 | B19: PMI-TOTO | C19: 85 | E19: =E18+C19-D19 -> 9627
A20: 43313 | B20: NINDYA LTM KSO-PUSK.CILILITAN | C20: 61 | E20: =E19+C20-D20 -> 9688
A21: 43313 | B21: INDONAKANO-PANASONIC | C21: 1 | E21: =E20+C21-D21 -> 9689 | F21: COCOK
A22: 43313 | B22: INDONAKANO-THAI SUMMIT | C22: 3 | E22: =E21+C22-D22 -> 9692
A23: 43344 | B23: INDONAKANO-SEIWA | C23: 96 | E23: =E22+C23-D23 -> 9788 | F23: COCOK
A24: 43374 | B24: INDONAKANO-SEIWA | C24: 51 | E24: =E23+C24-D24 -> 9839
A25: 43374 | B25: ACSET-MCC | C25: 10 | E25: =E24+C25-D25 -> 9849
A26: 43374 | B26: NINDYA KARYA-SDN 04 MERUYA | C26: 11 | E26: =E25+C26-D26 -> 9860
A27: 43374 | B27: NINDYA KARYA-PUSK.CMPK PUTIH | C27: 60 | E27: =E26+C27-D27 -> 9920 | F27: COCOK
A28: 43405 | B28: NINDYA KARYA-SDN KEB.JERUK 06 | C28: 4 | E28: =E27+C28-D28 -> 9924
A29: 43435 | B29: NINDYA KARYA-HARAPAN KITA | C29: 91 | E29: =E28+C29-D29 -> 10015 | F29: COCOK
A30: 13/1/2018 | B30: PMI-TOTO | C30: 21 | E30: =E29+C30-D30 -> 10036
A31: 13/1/2018 | B31: ACSET-MCC | C31: 20 | E31: =E30+C31-D31 -> 10056
A32: 13/1/2018 | B32: BHINEKA CP-AHM | C32: 11 | E32: =E31+C32-D32 -> 10067
A33: 15/1/2018 | B33: NINDYA-LTM KSO-JOHAR BARU | C33: 57 | E33: =E32+C33-D33 -> 10124
A34: 15/1/2018 | B34: BHINEKA-AHM | C34: 27 | E34: =E33+C34-D34 -> 10151
A35: 15/1/2018 | B35: ACSET-MCC | C35: 14 | E35: =E34+C35-D35 -> 10165
A36: 15/1/2018 | B36: WIKA-TRANS CIBUBUR | D36: 350 | E36: =E35+C36-D36 -> 9815
A37: 15/1/2018 | B37: WIKA-TRANS CIBUBUR | D37: 450 | E37: =E36+C37-D37 -> 9365
A38: 16/1/2018 | B38: NINDYA KARYA-SDN 04 MERUYA | C38: 2 | E38: =E37+C38-D38 -> 9367
A39: 16/1/2018 | B39: WIKA-TRANS CIBUBUR | D39: 400 | E39: =E38+C39-D39 -> 8967 | F39: COCOK
A40: 17/1/2018 | B40: NINDYA-LTM KSO-PUSK.CEGER | C40: 53 | E40: =E39+C40-D40 -> 9020
A41: 17/1/2018 | B41: NINDYA LTM KSO- PUSK. CILILTAN | C41: 35 | E41: =E40+C41-D41 -> 9055
A42: 17/1/2018 | B42: NINDYA LTM KSO-MENGGARAI | C42: 69 | E42: =E41+C42-D42 -> 9124
...

Sheet MF150
A2: NAMA BARANG : MF 150
A4: TGL | B4: NAMA PT-PROYEK | C4: MASUK | D4: KELUAR | E4: SISA | F4: KETERANGAN
B5: SISA STOK 2017 | E5: 524
A6: 13/1/2018 | B6: TOTAL-BBSI.JO | C6: 2 | E6: =E5+C6-D6 -> 526
A7: 27/2/2018 | B7: PT.BHINEKA-PERMATA BUANA | C7: 100 | E7: =E6+C7-D7 -> 626
A8: 28/2/2018 | B8: BHINEKA-PERMATA BUANA | C8: 100 | E8: =E7+C8-D8 -> 726 | F8: COCOK
A9: 24/5/2018 | B9: TBP-BBSI.JO | C9: 1 | E9: =E8+C9-D9 -> 727 | F9: COCOK
A10: 43165 | B10: PAK. HAJI | D10: 1 | E10: =E9+C10-D10 -> 726 | F10: COCOK

Sheet LD120
A2: NAMA BARANG : LD120
A4: TGL | B4: NAMA PT-PROYEK | C4: MASUK | D4: KELUAR | E4: SISA | F4: KETERANGAN
B5: SISA STOK 2017 | E5: 2089
A6: 22/2/2018 | B6: TBP-BURSA EFEK-SUDIRMAN | D6: 60 | E6: =E5+C6-D6 -> 2029
A7: 43134 | B7: TBP-BURSA EFEK SUDIRMAN | D7: 10 | E7: =E6+C7-D7 -> 2019
A8: 43134 | B8: TBP-BURSA EFEK SUDIRMAN | D8: 70 | E8: =E7+C8-D8 -> 1949
A9: 22/3/2018 | B9: TBP-BURSA EFEK SUDIRMAN | C9: 47 | E9: =E8+C9-D9 -> 1996
A10: 28/3/2018 | B10: TBP-BEJ - SUDIRMAN | C10: 91 | E10: =E9+C10-D10 -> 2087 | F10: COCOK
A11: 43224 | B11: GELOBAL-WISMA FAJAR | D11: 85 | E11: =E10+C11-D11 -> 2002
A12: 43255 | B12: GLOBAL-WISMA FAJAR | D12: 45 | E12: =E11+C12-D12 -> 1957 | F12: COCOK
A13: 17/4/2018 | B13: GELORA-WISMA FAJAR SENAYAN | D13: 32 | E13: =E12+C13-D13 -> 1925
A14: 18/4/2018 | B14: GELORA-WISMA FAJAR SENAYAN | D14: 84 | E14: =E13+C14-D14 -> 1841 | F14: COCOK
A15: 19/4/2018 | B15: GELORA-WISMA FAJAR SENAYAN | D15: 175 | E15: =E14+C15-D15 -> 1666 | F15: COCOK
A16: 43225 | B16: GELORA-WISMA FAJAR | D16: 30 | E16: =E15+C16-D16 -> 1636 | F16: COCOK
A17: 43286 | B17: GELORA-WISMA FAJAR | D17: 110 | E17: =E16+C17-D17 -> 1526
A18: 43165 | B18: BPK HAJI | D18: 4 | E18: =E17+C18-D18 -> 1522 | F18: COCOK

Sheet LD90(STF90)
A1: NAMA BARANG : LD90 (STF 90) STAIR TYPE FRAME 90
A3: TGL | B3: NAMA PT-PROYEK | C3: MASUK | D3: KELUAR | E3: SISA | F3: KETERANGAN
B4: SISA STOK 2017 | E4: 7475
A5: 43132 | B5: NINDYA KARYA-SDN 04 MERUYA 21+5 | C5: 26 | E5: =E4+C5-D5 -> 7501
A6: 43132 | B6: ACSET-MCC | C6: 10 | E6: =E5+C6-D6 -> 7511
A7: 43160 | B7: BHINEKA-AHM | C7: 110 | E7: =E6+C7-D7 -> 7621
A8: 43160 | B8: IDEA MANDIRI | C8: 10 | E8: =E7+C8-D8 -> 7631 | F8: COCOK
A9: 43191 | B9: BHINEKA-AHM | C9: 146 | E9: =E8+C9-D9 -> 7777 | F9: COCOK
A10: 43221 | B10: NINDYA KARYA-RS.HARKIT | C10: 24 | E10: =E9+C10-D10 -> 7801
A11: 43221 | B11: NINDYA KARYA-SDN 04 MERUYA | C11: 8 | E11: =E10+C11-D11 -> 7809
A12: 43221 | B12: BHINEKA-AHM | C12: 119 | E12: =E11+C12-D12 -> 7928
A13: 43221 | B13: INDONAKANO-PANASONIC GOBEL | C13: 332 | E13: =E12+C13-D13 -> 8260 | F13: COCOK
A14: 43252 | B14: NINDYA KARYA-HARAPAN KITA | C14: 142 | E14: =E13+C14-D14 -> 8402
A15: 43252 | B15: PMI-TOTO | C15: 30 | E15: =E14+C15-D15 -> 8432
A16: 43313 | B16: NINDYA LTM-KSO | C16: 3 | E16: =E15+C16-D16 -> 8435 | F16: COCOK
A17: 43344 | B17: BHINEKA-AHM | C17: 154 | E17: =E16+C17-D17 -> 8589 | F17: COCOK
A18: 43374 | B18: INDONAKANO-SEIWA | C18: 2 | E18: =E17+C18-D18 -> 8591
A19: 43374 | B19: ACSET-MCC | C19: 26 | E19: =E18+C19-D19 -> 8617
A20: 43374 | B20: NINDYA KARYA-SDN 04 MERUYA | C20: 4 | E20: =E19+C20-D20 -> 8621
A21: 43374 | B21: NINDYA KARYA-TAMBORA | C21: 24 | E21: =E20+C21-D21 -> 8645
A22: 43374 | B22: NINDYA KARYA-PUSK.CMPK PUTIH | C22: 2 | E22: =E21+C22-D22 -> 8647 | F22: COCOK
A23: 43405 | B23: NINDYA KARYA-SDN KEB.JERUK 06 | C23: 15 | E23: =E22+C23-D23 -> 8662
A24: 43405 | B24: BHINEKA-AHM | C24: 224 | E24: =E23+C24-D24 -> 8886
A25: 43435 | B25: NINDYA KARYA-HARAPAN KITA | C25: 91 | E25: =E24+C25-D25 -> 8977
A26: 43405 | B26: NINDYA - LTM KSO | C26: 167 | E26: =E25+C26-D26 -> 9144 | F26: COCOK
A27: 13/1/2018 | B27: BHINEKA CP-AHM | C27: 20 | E27: =E26+C27-D27 -> 9164
A28: 15/1/2018 | B28: BHINEKA-AHM | C28: 23 | E28: =E27+C28-D28 -> 9187
A29: 15/1/2018 | B29: ACSET-MCC | C29: 23 | E29: =E28+C29-D29 -> 9210
A30: 16/1/2018 | B30: INDONAKANO-THAI SUMMIT | C30: 60 | E30: =E29+C30-D30 -> 9270 | F30: COCOK
A31: 17/1/2018 | B31: NINDYA LTM KSO-PUSK.CILILITAN | C31: 3 | E31: =E30+C31-D31 -> 9273
A32: 17/1/2018 | B32: NINDYA LTM KSO-MENGGARAI | C32: 40 | E32: =E31+C32-D32 -> 9313
A33: 17/1/2018 | B33: PMI-TOTO(CIKOKOL) | C33: 77 | E33: =E32+C33-D33 -> 9390
A34: 17/1/2018 | B34: NINDYA KARYA-RS.HARKIT | C34: 49 | E34: =E33+C34-D34 -> 9439
A35: 17/1/2018 | B35: JKA-JOB GDNG | C35: 4 | E35: =E34+C35-D35 -> 9443
A36: 18/1/2018 | B36: INDONAKANO-THAI SUMMIT | C36: 38 | E36: =E35+C36-D36 -> 9481
A37: 18/1/2018 | B37: TBP-LAVIE | C37: 10 | E37: =E36+C37-D37 -> 9491
A38: 18/1/2018 | B38: NKE-CNQC-CHADSTONE | D38: 100 | E38: =E37+C38-D38 -> 9391
A39: 19/1/2018 | B39: NINDYA KARYA-HARAPAN KITA | C39: 26 | E39: =E38+C39-D39 -> 9417
A40: 19/1/2018 | B40: ACSET-MCC | C40: 13 | E40: =E39+C40-D40 -> 9430 | F40: COCOK
A41: 20/1/2018 | B41: LENA-MENTENG | C41: 51 | E41: =E40+C41-D41 -> 9481 | F41: COCOK
...

Sheet LD50
A2: NAMA BARANG : LD50
A4: TGL | B4: NAMA PT-PROYEK | C4: MASUK | D4: KELUAR | E4: SISA | F4: KETERANGAN
B5: SISA STOK 2017 | E5: 1289
A6: 43132 | B6: GLOBAL-AROSA | C6: 3 | E6: =E5+C6-D6 -> 1292
A7: 43132 | B7: GLOBAL-AROSA | C7: 28 | E7: =E6+C7-D7 -> 1320
A8: 43191 | B8: GLOBAL-AROSA | C8: 2 | E8: =E7+C8-D8 -> 1322
A9: 43191 | B9: POLABAJA-TOYOTA BT CEPER | C9: 75 | E9: =E8+C9-D9 -> 1397
A10: 43133 | B10: GLOBAL-AROSA | C10: 46 | E10: =E9+C10-D10 -> 1443
A11: 43253 | B11: POLABAJA-TOYOTA BT CEPER | C11: 9 | E11: =E10+C11-D11 -> 1452
A12: 27/2/2018 | B12: GLOBAL-AROSA | C12: 7 | E12: =E11+C12-D12 -> 1459
A13: 15/3/2018 | B13: GELOBAL-AROSA | C13: 3 | E13: =E12+C13-D13 -> 1462
A14: 23/3/2018 | B14: GELOBAL-AROSA | C14: 22 | E14: =E13+C14-D14 -> 1484
A15: 43377 | B15: GELOBAL-AROSA | C15: 12 | E15: =E14+C15-D15 -> 1496
A16: 30/4/2018 | B16: VASTORINDO-TOTO | C16: 8 | E16: =E15+C16-D16 -> 1504
A17: 43136 | B17: GELORA-AROSA BINTARO | C17: 6 | E17: =E16+C17-D17 -> 1510
A18: 43164 | B18: BHINEKA-BALARAJA | C18: 160 | E18: =E17+C18-D18 -> 1670
A19: 43348 | B19: BHINEKA-BALARAJA | C19: 165 | E19: =E18+C19-D19 -> 1835
A20: 25/5/2018 | B20: BCP-BALARAJA | C20: 18 | E20: =E19+C20-D20 -> 1853
A21: 43196 | B21: GELORA-AROSA BINTARO | C21: 11 | E21: =E20+C21-D21 -> 1864 | F21: COCOK

Sheet CB220(301A)
A1: NAMA BARANG : CB220 (301A)
A3: TGL | B3: NAMA PT-PROYEK | C3: MASUK | D3: KELUAR | E3: SISA | F3: KETERANGAN
B4: SISA STOK 2017 | E4: 7202
A5: 43132 | B5: TBP-JO.JIEXPO | C5: 110 | E5: =E4+C5-D5 -> 7312
A6: 43160 | B6: INDONAKANO-PANASONIC GOBEL | C6: 1160 | E6: =E5+C6-D6 -> 8472 | F6: COCOK
A7: 43191 | B7: GLOBAL-AROSA | C7: 130 | E7: =E6+C7-D7 -> 8602 | F7: COCOK
A8: 43221 | B8: NINDYA KARYA-RS.HARKIT | C8: 12 | E8: =E7+C8-D8 -> 8614
A9: 43221 | B9: NINDYA.LTM KSO-PUSK.CEGER | C9: 39 | E9: =E8+C9-D9 -> 8653
A10: 42856 | B10: BHINEKA-AHM | C10: 90 | E10: =E9+C10-D10 -> 8743 | F10: COCOK
A11: 42887 | B11: TOTAL-BBSI.JO | C11: 400 | E11: =E10+C11-D11 -> 9143
A12: 43252 | B12: PMI-TOTO | C12: 100 | E12: =E11+C12-D12 -> 9243
A13: 43282 | B13: WIKA-TRANS CIBUBUR | D13: 600 | E13: =E12+C13-D13 -> 8643
A14: 43313 | B14: NINDYA.LTM KSO-PUSK.CILILITAN | C14: 10 | E14: =E13+C14-D14 -> 8653
A15: 43313 | B15: INDONAKANO-PANASONIC GOBEL | C15: 11 | E15: =E14+C15-D15 -> 8664
A16: 43313 | B16: WIKA-TRANS CIBUBUR | D16: 410 | E16: =E15+C16-D16 -> 8254 | F16: COCOK
A17: 43313 | B17: INDONAKANO-THAISUMIT | C17: 50 | E17: =E16+C17-D17 -> 8304
A18: 43344 | B18: INDONAKANO-SEIWA | C18: 170 | E18: =E17+C18-D18 -> 8474
A19: 42979 | B19: BHINEKA-AHM | C19: 215 | E19: =E18+C19-D19 -> 8689 | F19: COCOK
A20: 43374 | B20: INDONAKANO-SEIWA | C20: 52 | E20: =E19+C20-D20 -> 8741
A21: 43374 | B21: ACSET-VISTA | C21: 138 | E21: =E20+C21-D21 -> 8879
A22: 43374 | B22: NINDYA KARYA-SDN 04 MERUYA | C22: 23 | E22: =E21+C22-D22 -> 8902
A23: 43374 | B23: WIKA-TRANS CIBUBUR | D23: 300 | E23: =E22+C23-D23 -> 8602 | F23: COCOK
A24: 43405 | B24: TOTAL-BBSI.JO | C24: 336 | E24: =E23+C24-D24 -> 8938
A25: 43405 | B25: NINDYA KARYA-SDN KEB.JERUK 06 | C25: 5 | E25: =E24+C25-D25 -> 8943
A26: 43405 | B26: WIKA-TRANS CIBUBUR | D26: 400 | E26: =E25+C26-D26 -> 8543
A27: 43435 | B27: TBP-RS.GRAHA | C27: 20 | E27: =E26+C27-D27 -> 8563
A28: 43435 | B28: NINDYA KARYA-HARAPAN KITA | C28: 183 | E28: =E27+C28-D28 -> 8746
A29: 43435 | B29: BHINEKA-AHM | C29: 464 | E29: =E28+C29-D29 -> 9210
A30: 43435 | B30: WIKA-TRANS CIBUBUR 100+380 | D30: 480 | E30: =E29+C30-D30 -> 8730 | F30: COCOK
A31: 13/1/2018 | B31: PMI-TOTO | C31: 182 | E31: =E30+C31-D31 -> 8912
A32: 13/1/2018 | B32: BHINEKA-AHM 79+11 | C32: 90 | E32: =E31+C32-D32 -> 9002
A33: 13/1/2018 | B33: WIKA-TRANS CIBUBUR 400 | D33: 400 | E33: =E32+C33-D33 -> 8602
A34: 14/1/2018 | B34: WIKA-TRANS CIBUBUR 420 | D34: 420 | E34: =E33+C34-D34 -> 8182
A35: 15/1/2018 | B35: BHINEKA-AHM 47+8 | C35: 55 | E35: =E34+C35-D35 -> 8237
A36: 15/1/2018 | B36: WIKA-TRANS CIBUBUR | D36: 350 | E36: =E35+C36-D36 -> 7887
A37: 15/1/2018 | B37: WIKA-TRANS CIBUBUR | D37: 450 | E37: =E36+C37-D37 -> 7437
A38: 16/1/2018 | B38: ACSET-MCC | C38: 72 | E38: =E37+C38-D38 -> 7509
A39: 16/1/2018 | B39: NINDYA KARYA-SDN 04 MERUYA | C39: 3 | E39: =E38+C39-D39 -> 7512
A40: 16/1/2018 | B40: INDONAKANO-THAI SUMMIT | C40: 28 | E40: =E39+C40-D40 -> 7540
A41: 16/1/2018 | B41: WIKA-TRANS CIBUBUR | D41: 400 | E41: =E40+C41-D41 -> 7140 | F41: COCOK
...

Sheet CB193
A2: NAMA BARANG : CB 193
A4: TGL | B4: NAMA PT-PROYEK | C4: MASUK | D4: KELUAR | E4: SISA | F4: KETERANGAN
B5: SISA STOK 2017 | E5: 3253
A6: 43160 | B6: INDONAKANO-PANASONIC GOBEL | C6: 420 | E6: =E5+C6-D6 -> 3673
A7: 43160 | B7: IDEA MANDIRI | C7: 80 | E7: =E6+C7-D7 -> 3753 | F7: COCOK
A8: 43191 | B8: GLOBAL-AROSA | C8: 18 | E8: =E7+C8-D8 -> 3771 | F8: COCOK
A9: 43221 | B9: NINDYA KARYA-RS.HARKIT | C9: 5 | E9: =E8+C9-D9 -> 3776
A10: 43221 | B10: NINDYA.LTM KSO-PUSK.CEGER | C10: 41 | E10: =E9+C10-D10 -> 3817
A11: 42856 | B11: BHINEKA-AHM | C11: 19 | E11: =E10+C11-D11 -> 3836 | F11: COCOK
A12: 43252 | B12: PMI-TOTO | C12: 30 | E12: =E11+C12-D12 -> 3866
A13: 43313 | B13: NINDYA.LTM KSO-PUSK.CILILITAN | C13: 75 | E13: =E12+C13-D13 -> 3941
A14: 43313 | B14: INDONAKANO-PANASONIC GOBEL | C14: 42 | E14: =E13+C14-D14 -> 3983 | F14: COCOK
A15: 43313 | B15: INDONAKANO-THAISUMMIT | C15: 160 | E15: =E14+C15-D15 -> 4143
A16: 43344 | B16: BHINEKA-AHM | C16: 450 | E16: =E15+C16-D16 -> 4593 | F16: COCOK
A17: 43374 | B17: INDONAKANO-SEIWA | C17: 8 | E17: =E16+C17-D17 -> 4601
A18: 43374 | B18: NINDYA KARYA-SDN 04 MERUYA | C18: 20 | E18: =E17+C18-D18 -> 4621
A19: 43374 | B19: NINDYA KARYA-PUSK.CMPK PUTIH | C19: 20 | E19: =E18+C19-D19 -> 4641 | F19: COCOK
A20: 43405 | B20: NINDYA KARYA-SDN KEB.JERUK 06 | C20: 35 | E20: =E19+C20-D20 -> 4676
A21: 43405 | B21: BHINEKA-AHM 460+52 | C21: 512 | E21: =E20+C21-D21 -> 5188
A22: 43435 | B22: NINDYA KARYA-HARAPAN KITA | C22: 118 | E22: =E21+C22-D22 -> 5306
A23: 13/1/2018 | B23: PMI-TOTO | C23: 42 | E23: =E22+C23-D23 -> 5348
A24: 13/1/2018 | B24: BHINEKA-AHM 40+11 | C24: 51 | E24: =E23+C24-D24 -> 5399
A25: 15/1/2018 | B25: BHINEKA-AHM | C25: 8 | E25: =E24+C25-D25 -> 5407
A26: 16/1/2018 | B26: ACSET-MCC | C26: 81 | E26: =E25+C26-D26 -> 5488
A27: 16/1/2018 | B27: NINDYA KARYA-SDN 04 MERUYA | C27: 4 | E27: =E26+C27-D27 -> 5492
A28: 16/1/2018 | B28: INDONAKANO-THAI SUMMIT | C28: 108 | E28: =E27+C28-D28 -> 5600 | F28: COCOK
A29: 17/1/2018 | B29: NINDYA-LTM KSO-PUSK.CEGER | C29: 5 | E29: =E28+C29-D29 -> 5605
A30: 17/1/2018 | B30: NINDYA LTM KSO-PUSK.CILILITAN | C30: 17 | E30: =E29+C30-D30 -> 5622
A31: 17/1/2018 | B31: NINDYA LTM KSO-MENGGARAI | C31: 35 | E31: =E30+C31-D31 -> 5657
A32: 17/1/2018 | B32: NINDYA KARYA-RS.HARKIT | C32: 64 | E32: =E31+C32-D32 -> 5721
A33: 17/1/2018 | B33: JKA-JOB GDNG | C33: 3 | E33: =E32+C33-D33 -> 5724
A34: 18/1/2018 | B34: INDONAKANO-THAI SUMMIT | C34: 11 | E34: =E33+C34-D34 -> 5735
A35: 18/1/2018 | B35: NKE-CNQC-CHADSTONE | D35: 100 | E35: =E34+C35-D35 -> 5635
A36: 19/1/2018 | B36: NINDYA KARYA-HARAPAN KITA | C36: 36 | E36: =E35+C36-D36 -> 5671 | F36: COCOK
A37: 24/1/2018 | B37: INDONAKANO-HIRUTA | C37: 25 | E37: =E36+C37-D37 -> 5696
A38: 24/1/2018 | B38: NINDYA KARYA-RS.HARKIT | C38: 15 | E38: =E37+C38-D38 -> 5711 | F38: COCOK
A39: 25/1/2018 | B39: NINDYA-LTM KSO.PUSK-MANGGARAI | C39: 80 | E39: =E38+C39-D39 -> 5791
A40: 26/1/2018 | B40: CONCREAT-JL.MPR R.DLM CILANDAK | C40: 50 | E40: =E39+C40-D40 -> 5841
A41: 26/1/2018 | B41: INDONAKANO-PANASONIC GOBEL | C41: 7 | E41: =E40+C41-D41 -> 5848
A42: 26/1/2018 | B42: PMI-TOTO | C42: 30 | E42: =E41+C42-D42 -> 5878
...

Sheet CB185
A2: NAMA BARANG : CB185
A4: TGL | B4: NAMA PT-PROYEK | C4: MASUK | D4: KELUAR | E4: SISA | F4: KETERANGAN
B5: SISA STOK 2017 | E5: 816
A6: 43191 | B6: GLOBAL-AROSA | C6: 35 | E6: =E5+C6-D6 -> 851
A7: 43133 | B7: GLOBAL-AROSA | C7: 40 | E7: =E6+C7-D7 -> 891
A8: 20/2/2018 | B8: POLABAJA-INDRAMAYU | C8: 153 | E8: =E7+C8-D8 -> 1044
A9: 27/2/2018 | B9: GELORA-BINTARO | C9: 5 | E9: =E8+C9-D9 -> 1049
A10: 27/2/2018 | B10: GELORA-BINTARO | C10: 12 | E10: =E9+C10-D10 -> 1061
A11: 43346 | B11: POLABAJA-INDRAMAYU | C11: 7 | E11: =E10+C11-D11 -> 1068
A12: 15/3/2018 | B12: GELORA-BINTARO | C12: 14 | E12: =E11+C12-D12 -> 1082
A13: 23/3/2018 | B13: GELOBAL-AROSA | C13: 20 | E13: =E12+C13-D13 -> 1102
A14: 23/3/2018 | B14: GELOBAL-AROSA | C14: 28 | E14: =E13+C14-D14 -> 1130
A15: 43377 | B15: GELOBAL-AROSA | C15: 11 | E15: =E14+C15-D15 -> 1141 | F15: COCOK
A16: 19/4/2018 | B16: GELOBAL-AROSA | C16: 17 | E16: =E15+C16-D16 -> 1158 | F16: COCOK
A17: 43136 | B17: GELORA-AROSA BINTARO | C17: 17 | E17: =E16+C17-D17 -> 1175 | F17: COCOK
A18: 25/5/2018 | B18: BCP-BALARAJA | C18: 280 | E18: =E17+C18-D18 -> 1455
A19: 25/5/2018 | B19: BCP-BALARAJA | C19: 45 | E19: =E18+C19-D19 -> 1500 | F19: COCOK
A20: 43196 | B20: GELORA-AROSA BINTARO | C20: 13 | E20: =E19+C20-D20 -> 1513 | F20: COCOK

Sheet CB172(173)
A2: NAMA BARANG : CB 172 /173
A4: TGL | B4: NAMA PT-PROYEK | C4: MASUK | D4: KELUAR | E4: SISA | F4: KETERANGAN
B5: Sisa stok 2017 | E5: 1909
A6: 43283 | B6: NINDYA-LTM KSO-PUSK.CEMPAKA PTH | C6: 12 | E6: =E5+C6-D6 -> 1921
A7: 43314 | B7: NINDYA-LTM KSO-PUSK.MANGGARAI | C7: 42 | E7: =E6+C7-D7 -> 1963
A8: 27/2/2018 | B8: NINDYA-LTM KSO-PUSK.GDG.X-DERES | C8: 18 | E8: =E7+C8-D8 -> 1981 | F8: COCOK

Sheet CB 205
A2: NAMA BARANG : CB 205
A4: TGL | B4: NAMA PT-PROYEK | C4: MASUK | D4: KELUAR | E4: SISA | F4: KETERANGAN
B5: Sisa stok 2017 | E5: 1041
A6: 22/2/2018 | B6: TBP-BURSA EFEK-SUDIRMAN | D6: 120 | E6: =E5+C6-D6 -> 921
A7: 43134 | B7: TBP-BURSA EFEK SUDIRMAN | D7: 114 | E7: =E6+C7-D7 -> 807
A8: 22/3/2018 | B8: TBP-BURSA EFEK SUDIRMAN | C8: 90 | E8: =E7+C8-D8 -> 897 | F8: COCOK
A9: 26/3/2018 | B9: TBP-BEJ - SUDIRMAN | C9: 50 | E9: =E8+C9-D9 -> 947
A10: 26/3/2018 | B10: TBP-BEJ - SUDIRMAN | C10: 51 | E10: =E9+C10-D10 -> 998 | F10: COCOK
A11: 30/3/2018 | B11: TBP-BURSA EFEK SUDIRMAN | C11: 16 | E11: =E10+C11-D11 -> 1014
A12: 31/3/2018 | B12: NKE-DAM LARONA | D12: 280 | E12: =E11+C12-D12 -> 734 | F12: COCOK
A13: 43224 | B13: GELOBAL-WISMA FAJAR | D13: 130 | E13: =E12+C13-D13 -> 604
A14: 43255 | B14: GLOBAL-WISMA FAJAR | D14: 65 | E14: =E13+C14-D14 -> 539 | F14: COCOK
A15: 17/4/2018 | B15: GELORA-WISMA FAJAR SENAYAN | D15: 60 | E15: =E14+C15-D15 -> 479
A16: 18/4/2018 | B16: GELORA-WISMA FAJAR SENAYAN | D16: 90 | E16: =E15+C16-D16 -> 389 | F16: COCOK
A17: 19/4/2018 | B17: GELORA-WISMA FAJAR SENAYAN | D17: 70 | E17: =E16+C17-D17 -> 319 | F17: COCOK
A18: 43225 | B18: GELORA-WISMA FAJAR SENAYAN | D18: 200 | E18: =E17+C18-D18 -> 119 | F18: COCOK

Sheet CB136
A2: NAMA BARANG : CB 136
A4: TGL | B4: NAMA PT-PROYEK | C4: MASUK | D4: KELUAR | E4: SISA | F4: KETERANGAN
B5: SISA STOK 2017 | E5: 769

Sheet JOIN PIN
A2: NAMA BARANG : JOINPIN (JP)
A4: TGL | B4: NAMA PT-PROYEK | C4: MASUK | D4: KELUAR | E4: SISA | F4: KETERANGAN
B5: SISA STOK 2017 | E5: 12540
A6: 43132 | B6: TBP-LAVIE | C6: 27 | E6: =E5+C6-D6 -> 12567
A7: 43132 | B7: TBP-JO.JIEXPO | C7: 236 | E7: =E6+C7-D7 -> 12803
A8: 43160 | B8: INDONAKANO-PANASONIC GOBEL | C8: 876 | E8: =E7+C8-D8 -> 13679
A9: 43160 | B9: BHINEKA-AHM 17+16 | C9: 33 | E9: =E8+C9-D9 -> 13712 | F9: COCOK
A10: 43191 | B10: BHINEKA-AHM | C10: 14 | E10: =E9+C10-D10 -> 13726
A11: 43191 | B11: TBP-LAVIE | C11: 22 | E11: =E10+C11-D11 -> 13748
A12: 43191 | B12: TBP-BBSI.JO | C12: 100 | E12: =E11+C12-D12 -> 13848 | F12: COCOK
A13: 43221 | B13: TBP-LAVIE | C13: 15 | E13: =E12+C13-D13 -> 13863
A14: 43221 | B14: NINDYA KARYA-RS.HARKIT | C14: 14 | E14: =E13+C14-D14 -> 13877
A15: 43221 | B15: NINDYA.LTM KSO-PUSK.CEGER 291+10 | C15: 301 | E15: =E14+C15-D15 -> 14178
A16: 43221 | B16: BHINEKA - AHM | C16: 1585 | E16: =E15+C16-D16 -> 15763 | F16: COCOK
A17: 43252 | B17: NINDYA KARYA-HARAPAN KITA | C17: 104 | E17: =E16+C17-D17 -> 15867
A18: 43282 | B18: WIKA-TRANS CIBUBUR | D18: 650 | E18: =E17+C18-D18 -> 15217
A19: 43313 | B19: NINYA LTM KSO-PUSK.CILILITAN | C19: 121 | E19: =E18+C19-D19 -> 15338
A20: 43313 | B20: WIKA-TRANS CIBUBUR | D20: 800 | E20: =E19+C20-D20 -> 14538 | F20: COCOK
A21: 43313 | B21: INDONAKANO-THAI SUMMIT | C21: 94 | E21: =E20+C21-D21 -> 14632
A22: 43313 | B22: ACSET-MCC | C22: 6 | E22: =E21+C22-D22 -> 14638
A23: 43344 | B23: TOTAL-BBSI.JO | C23: 2 | E23: =E22+C23-D23 -> 14640
A24: 43374 | B24: INDONAKANO-SEIWA | C24: 980 | E24: =E23+C24-D24 -> 15620
A25: 43374 | B25: NINDYA KARYA-PUSK.CMPK PUTIH | C25: 5 | E25: =E24+C25-D25 -> 15625
A26: 43374 | B26: WIKA-TRANS CIBUBUR | D26: 600 | E26: =E25+C26-D26 -> 15025 | F26: COCOK
A27: 43405 | B27: TOTAL-BBSI.JO | C27: 400 | E27: =E26+C27-D27 -> 15425
A28: 43405 | B28: NINDYA KARYA-SDN KEB.JERUK 06 | C28: 53 | E28: =E27+C28-D28 -> 15478
A29: 43405 | B29: WIKA-TRANS CIBUBUR | D29: 800 | E29: =E28+C29-D29 -> 14678
A30: 43435 | B30: NINDYA KARYA-HARAPAN KITA | C30: 65 | E30: =E29+C30-D30 -> 14743
A31: 43435 | B31: WIKA-TRANS CIBUBUR 200+800 | D31: 1000 | E31: =E30+C31-D31 -> 13743 | F31: COCOK
A32: 13/1/2018 | B32: PMI-TOTO | C32: 300 | E32: =E31+C32-D32 -> 14043
A33: 13/1/2018 | B33: BHINEKA-AHM | C33: 13 | E33: =E32+C33-D33 -> 14056
A34: 13/1/2018 | B34: TBP-LAVIE | C34: 4 | E34: =E33+C34-D34 -> 14060
A35: 13/1/2018 | B35: WIKA-TRANS CIBUBUR | D35: 800 | E35: =E34+C35-D35 -> 13260
A36: 15/1/2018 | B36: NINDYA-LTM KSO-JOHAR BARU | C36: 500 | E36: =E35+C36-D36 -> 13760
A37: 15/1/2018 | B37: BHINEKA-AHM | C37: 14 | E37: =E36+C37-D37 -> 13774
A38: 15/1/2018 | B38: ACSET-MCC | C38: 2 | E38: =E37+C38-D38 -> 13776
A39: 16/1/2018 | B39: NINDYA KARYA-SDN 04 MERUYA | C39: 120 | E39: =E38+C39-D39 -> 13896
A40: 16/1/2018 | B40: INDONAKANO-THAI SUMMIT | C40: 100 | E40: =E39+C40-D40 -> 13996 | F40: COCOK
A41: 17/1/2018 | B41: NINDYA-LTM KSO-PUSK.CEGER | C41: 100 | E41: =E40+C41-D41 -> 14096
A42: 17/1/2018 | B42: NINDYA LTM KSO-PUSK.CILILITAN | C42: 111 | E42: =E41+C42-D42 -> 14207
...

Sheet JB 60
A2: NAMA BARANG : JACK BASE 60
A4: TGL | B4: NAMA PT-PROYEK | C4: MASUK | D4: KELUAR | E4: SISA | F4: STOK GUDANG WARDI | G4: KETERANGAN
B5: SISA STOK 2017 | E5: 5968
A6: 43132 | B6: NINDYA KARYA-04 MERUYA | C6: 57 | E6: =E5+C6-D6 -> 6025
A7: 43132 | B7: GLOBAL-AROSA | C7: 2 | E7: =E6+C7-D7 -> 6027
A8: 43132 | B8: GLOBAL-AROSA | C8: 109 | E8: =E7+C8-D8 -> 6136
A9: 43132 | B9: ACSET-MCC | C9: 151 | E9: =E8+C9-D9 -> 6287
A10: 43160 | B10: INDONAKANO-PANASONIC GOBEL 39+102 | C10: 141 | E10: =E9+C10-D10 -> 6428
A11: 43160 | B11: BHINEKA-AHM | C11: 150 | E11: =E10+C11-D11 -> 6578
A12: 43160 | B12: WIKA-TRANS CIBUBUR | D12: 400 | E12: =E11+C12-D12 -> 6178 | G12: COCOK
A13: 43191 | B13: GLOBAL-AROSA | C13: 5 | E13: =E12+C13-D13 -> 6183
A14: 43191 | B14: GLOBAL-AROSA | C14: 77 | E14: =E13+C14-D14 -> 6260
A15: 43191 | B15: TBP-BBSI.JO | C15: 50 | E15: =E14+C15-D15 -> 6310 | G15: COCOK
A16: 43221 | B16: NINDYA KARYA-RS.HARKIT | C16: 200 | E16: =E15+C16-D16 -> 6510
A17: 43221 | B17: NINDYA.LTM KSO-PUSK.CEGER | C17: 192 | E17: =E16+C17-D17 -> 6702
A18: 43221 | B18: BHINEKA - AHM 180+50 | C18: 230 | E18: =E17+C18-D18 -> 6932
A19: 43221 | B19: WIKA-TRANS CIBUBUR 400+400 | D19: 800 | E19: =E18+C19-D19 -> 6132 | G19: COCOK
A20: 43252 | B20: NINDYA KARYA-HARAPAN KITA 180+20+6 | C20: 206 | E20: =E19+C20-D20 -> 6338
A21: 43252 | B21: PMI-TOTO | C21: 60 | E21: =E20+C21-D21 -> 6398
A22: 43252 | B22: WIKA-TRANS CIBUBUR 676+324 | D22: 1000 | E22: =E21+C22-D22 -> 5398
A23: 43313 | B23: INDONAKANO-PANASONIC GOBEL | C23: 22 | E23: =E22+C23-D23 -> 5420 | G23: COCOK
A24: 43313 | B24: INDONAKANO-SEIWA | C24: 42 | E24: =E23+C24-D24 -> 5462
A25: 43313 | B25: INDONAKANO-THAISUMIT | C25: 170 | E25: =E24+C25-D25 -> 5632
A26: 42979 | B26: BHINEKA-AHM | C26: 207 | E26: =E25+C26-D26 -> 5839
A27: 42979 | B27: BHINEKA-AHM | C27: 83 | E27: =E26+C27-D27 -> 5922
A28: 42979 | B28: WIKA-TRANS CIBUBUR | D28: 400 | E28: =E27+C28-D28 -> 5522 | G28: COCOK
A29: 43374 | B29: INDONAKANO-SEIWA | C29: 50 | E29: =E28+C29-D29 -> 5572
A30: 43374 | B30: WIKA-TRANS CIBUBUR | D30: 400 | E30: =E29+C30-D30 -> 5172 | G30: COCOK
A31: 43405 | B31: NINDYA KARYA-SDN KEB.JERUK 06 | C31: 4 | E31: =E30+C31-D31 -> 5176
A32: 43405 | B32: BHINEKA-AHM 136+46 | C32: 182 | E32: =E31+C32-D32 -> 5358
A33: 43435 | B33: NINDYA KARYA-HARAPAN KITA | C33: 141 | E33: =E32+C33-D33 -> 5499 | G33: COCOK
A34: 13/1/2018 | B34: PMI-TOTO | C34: 52 | E34: =E33+C34-D34 -> 5551
A35: 13/1/2018 | B35: BHINEKA-AHM | C35: 3 | E35: =E34+C35-D35 -> 5554
A36: 15/1/2018 | B36: NINDYA-LTM KSO-JOHAR BARU 24+10+2 | C36: 36 | E36: =E35+C36-D36 -> 5590
A37: 15/1/2018 | B37: ACSET-MCC | C37: 200 | E37: =E36+C37-D37 -> 5790
A38: 16/1/2018 | B38: INDONAKANO-HIRUTA | C38: 137 | E38: =E37+C38-D38 -> 5927
A39: 16/1/2018 | B39: INDONAKANO-THAI SUMMIT | C39: 35 | E39: =E38+C39-D39 -> 5962
A40: 17/1/2018 | B40: NINDYA-LTM KSO-PUSK.CEGER | C40: 9 | E40: =E39+C40-D40 -> 5971
A41: 17/1/2018 | B41: PMI-TOTO(CIKOKOL) | C41: 30 | E41: =E40+C41-D41 -> 6001
A42: 17/1/2018 | B42: NINDYA KARYA-RS.HARKIT | C42: 382 | E42: =E41+C42-D42 -> 6383
...

Sheet UHEAD 60
A1: NAMA BARANG : U-HEAD JACK 60
A3: TGL | B3: NAMA PROYEK | C3: MASUK | D3: KELUAR | E3: SISA | F3: KETERANGAN
B4: SISA STOK 2017 | E4: 4534
A5: 43132 | B5: NINDYA KARYA-SDDN 04 MERUYA | C5: 64 | E5: =E4+C5-D5 -> 4598
A6: 43132 | B6: GLOBAL-AROSA | C6: 2 | E6: =E5+C6-D6 -> 4600
A7: 43132 | B7: GLOBAL-AROSA | C7: 8 | E7: =E6+C7-D7 -> 4608
A8: 43132 | B8: ACSET-MCC | C8: 150 | E8: =E7+C8-D8 -> 4758
A9: 43132 | B9: ACSET-MCC | C9: 43 | E9: =E8+C9-D9 -> 4801
A10: 43160 | B10: INDONAKANO-PANASONIC GOBEL | C10: 124 | E10: =E9+C10-D10 -> 4925
A11: 43160 | B11: BHINEKA-AHM 80+116+99+36+1 | C11: 332 | E11: =E10+C11-D11 -> 5257
A12: 43160 | B12: BHINEKA-AHM | C12: 200 | E12: =E11+C12-D12 -> 5457
A13: 43160 | B13: WIKA-TRANS CIBUBUR | D13: 400 | E13: =E12+C13-D13 -> 5057 | F13: COCOK
A14: 43191 | B14: GLOBAL-AROSA 18+4 | C14: 22 | E14: =E13+C14-D14 -> 5079
A15: 43191 | B15: GLOBAL-AROSA | C15: 3 | E15: =E14+C15-D15 -> 5082
A16: 43191 | B16: TBP-BBSI.JO | C16: 50 | E16: =E15+C16-D16 -> 5132 | F16: COCOK
A17: 43221 | B17: NINDYA KARYA-RS.HARKIT | C17: 325 | E17: =E16+C17-D17 -> 5457
A18: 43221 | B18: NINDYA.LTM KSO-PUSK.CEGER | C18: 32 | E18: =E17+C18-D18 -> 5489
A19: 42856 | B19: BHINEKA-AHM 75+80 | C19: 155 | E19: =E18+C19-D19 -> 5644
A20: 43221 | B20: WIKA-TRANS CIBUBUR 400+400 | D20: 800 | E20: =E19+C20-D20 -> 4844 | F20: COCOK
A21: 43252 | B21: NINDYA KARYA-HARIKIT 213+6+8 | C21: 227 | E21: =E20+C21-D21 -> 5071
A22: 43252 | B22: PMI-TOTO | C22: 118 | E22: =E21+C22-D22 -> 5189
A23: 43252 | B23: WIKA-TRANS CIBUBUR 600+400 | D23: 1000 | E23: =E22+C23-D23 -> 4189
A24: 43313 | B24: NINYA LTM KSO-PUSK.CILILITAN | C24: 9 | E24: =E23+C24-D24 -> 4198
A25: 43313 | B25: INDONAKANO-PANASONIC GOBEL | C25: 33 | E25: =E24+C25-D25 -> 4231 | F25: COCOK
A26: 43313 | B26: INDONAKANO-SEIWA | C26: 5 | E26: =E25+C26-D26 -> 4236
A27: 43313 | B27: INDONAKANO-THAISUMMIT | C27: 15 | E27: =E26+C27-D27 -> 4251
A28: 42979 | B28: BHINEKA-AHM | C28: 248 | E28: =E27+C28-D28 -> 4499
A29: 42979 | B29: BHINEKA-AHM | C29: 84 | E29: =E28+C29-D29 -> 4583
A30: 42979 | B30: WIKA-CIBUBUR | D30: 400 | E30: =E29+C30-D30 -> 4183 | F30: COCOK
A31: 43374 | B31: NINDYA KARYA-SDN 04 MERUYA | C31: 2 | E31: =E30+C31-D31 -> 4185
A32: 43374 | B32: WIKA-TRANS CIBUBUR | D32: 400 | E32: =E31+C32-D32 -> 3785 | F32: COCOK
A33: 43405 | B33: NINDYA KARYA-SDN KEB.JERUK 06 | C33: 3 | E33: =E32+C33-D33 -> 3788
A34: 43405 | B34: BHINEKA-AHM 111+51 | C34: 162 | E34: =E33+C34-D34 -> 3950
A35: 43435 | B35: NINDYA KARYA-HARAPAN KITA | C35: 347 | E35: =E34+C35-D35 -> 4297
A36: 43435 | B36: BHINEKA-AHM 184+125+2 | C36: 311 | E36: =E35+C36-D36 -> 4608 | F36: COCOK
A37: 13/1/2018 | B37: PMI-TOTO | C37: 87 | E37: =E36+C37-D37 -> 4695
A38: 13/1/2018 | B38: BHINEKA-AHM 50+28 | C38: 78 | E38: =E37+C38-D38 -> 4773
A39: 15/1/2018 | B39: ACSET-MCC 84+6 | C39: 90 | E39: =E38+C39-D39 -> 4863
A40: 16/1/2018 | B40: INDONAKANO-HIRUTA | C40: 5 | E40: =E39+C40-D40 -> 4868
A41: 16/1/2018 | B41: INDONAKANO-THAI SUMMIT | C41: 24 | E41: =E40+C41-D41 -> 4892 | F41: COCOK
...

Sheet JB40
A2: NAMA BARANG : JB40
A4: TGL | B4: NAMA PT-PROYEK | C4: MASUK | D4: KELUAR | E4: SISA | F4: KETERANGAN
B5: Sisa stok 2017 | E5: 370
A6: 42856 | B6: BHINEKA-AHM | C6: 25 | E6: =E5+C6-D6 -> 395
A7: 43405 | B7: BHINEKA-AHM | C7: 4 | E7: =E6+C7-D7 -> 399
A8: 43435 | B8: BHINEKA-AHM | C8: 48 | E8: =E7+C8-D8 -> 447
A9: 43435 | B9: BPK-SAIDI | D9: 30 | E9: =E8+C9-D9 -> 417
A10: 13/1/2018 | B10: BHINEKA-AHM 24+3 | C10: 27 | E10: =E9+C10-D10 -> 444
A11: 16/1/2018 | B11: EVI JAYA-SAEDI CENGKARENG | D11: 42 | E11: =E10+C11-D11 -> 402
A12: 23/1/2018 | B12: ACSET-WEST VISTA | C12: 50 | E12: =E11+C12-D12 -> 452
A13: 25/1/2018 | B13: ACSET-WEST VISTA | C13: 24 | E13: =E12+C13-D13 -> 476
A14: 43222 | B14: NINDYA -KTM KSO | C14: 13 | E14: =E13+C14-D14 -> 489
A15: 43345 | B15: TBP-SEQUIS SUDIRMAN | D15: 100 | E15: =E14+C15-D15 -> 389
A16: 26/2/2018 | B16: NINDYA-LTM KSO.PUSK-X-DERES | C16: 5 | E16: =E15+C16-D16 -> 394 | F16: COCOK
A17: 43103 | B17: BHINEKA-AHM | C17: 20 | E17: =E16+C17-D17 -> 414
A18: 43254 | B18: BCP-AHM | C18: 4 | E18: =E17+C18-D18 -> 418
A19: 43376 | B19: BCP-AHM | C19: 9 | E19: =E18+C19-D19 -> 427
A20: 43376 | B20: INDONAKANO-SEIWA | D20: 20 | E20: =E19+C20-D20 -> 407
A21: 26/3/2018 | B21: INDONAKANO-SEIWA | C21: 22 | E21: =E20+C21-D21 -> 429
A22: 43438 | B22: BCP-AHM 23+13 | C22: 36 | E22: =E21+C22-D22 -> 465 | F22: COCOK
A23: 20/4/2018 | B23: TBP-VERDE | D23: 50 | E23: =E22+C23-D23 -> 415 | F23: COCOK
A24: 21/4/2018 | B24: NKE-WCT KUNIGAN | D24: 90 | E24: =E23+C24-D24 -> 325 | F24: COCOK
A25: 22/5/2018 | B25: BCP-AHM | C25: 5 | E25: =E24+C25-D25 -> 330
A26: 22/5/2018 | B26: BCP-AHM | C26: 2 | E26: =E25+C26-D26 -> 332 | F26: COCOK
A27: 31/5/2018 | B27: NKE-WCT | C27: 79 | E27: =E26+C27-D27 -> 411 | F27: COCOK
A28: 43226 | B28: TBP-SQUISE TOWER | C28: 24 | E28: =E27+C28-D28 -> 435 | F28: COCOK

Sheet UH40
A2: NAMA BARANG : UH40
A4: TGL | B4: NAMA PT-PROYEK | C4: MASUK | D4: KELUAR | E4: SISA | F4: KETERANGAN
B5: Sisa stok 2017 | E5: 300
A6: 42856 | B6: BHINEKA-AHM | C6: 95 | E6: =E5+C6-D6 -> 395
A7: 43405 | B7: BHINEKA-AHM 77+5 | C7: 82 | E7: =E6+C7-D7 -> 477
A8: 43435 | B8: BHINEKA-AHM 112+3+3 | C8: 118 | E8: =E7+C8-D8 -> 595
A9: 43435 | B9: BPK-SAIDI | D9: 73 | E9: =E8+C9-D9 -> 522
A10: 13/1/2018 | B10: BHINEKA-AHM | C10: 10 | E10: =E9+C10-D10 -> 532
A11: 43222 | B11: NINDYA -KTM KSO | C11: 32 | E11: =E10+C11-D11 -> 564
A12: 43283 | B12: NINDYA - LTM KSO-PUSK.SEMPER BARAT III | C12: 8 | E12: =E11+C12-D12 -> 572
A13: 26/2/2018 | B13: NINDYA-LTM KSO.PUSK-X-DERES | C13: 5 | E13: =E12+C13-D13 -> 577
A14: 43103 | B14: BHINEKA-AHM | C14: 35 | E14: =E13+C14-D14 -> 612
A15: 43254 | B15: BCP-AHM | C15: 6 | E15: =E14+C15-D15 -> 618
A16: 43376 | B16: BCP-AHM | C16: 38 | E16: =E15+C16-D16 -> 656
A17: 43438 | B17: BCP-AHM | C17: 74 | E17: =E16+C17-D17 -> 730 | F17: COCOK
A18: 43378 | B18: BHINEKA-DELTA MAS | C18: 7 | E18: =E17+C18-D18 -> 737 | F18: COCOK
A19: 22/5/2018 | B19: BCP-AHM | C19: 8 | E19: =E18+C19-D19 -> 745
A20: 22/5/2018 | B20: BCP-AHM | C20: 1 | E20: =E19+C20-D20 -> 746 | F20: COCOK

Sheet TIANG.TANGGA
A1: NAMA BARANG : TIANG TANGGA
A3: TGL | B3: NAMA PT-PROYEK | C3: MASUK | D3: KELUAR | E3: SISA | F3: KETERANGAN
A4: 19/10/2017 | B4: EVI JAYA | C4: 50 | E4: 50
A5: 18/4/2018 | B5: TBP-VERDE KUNINGAN | D5: 10 | E5: =E4+C5-D5 -> 40

Sheet STAIR
A2: NAMA BARANG : STAIR / TANGGA
A4: TGL | B4: NAMA PT-PROYEK | C4: MASUK | D4: KELUAR | E4: SISA | F4: KETERANGAN
B5: Sisa stok 2017 | E5: 581
A6: 43191 | B6: TBP-BBSI.JO | C6: 12 | E6: =E5+C6-D6 -> 593 | F6: COCOK
A7: 43344 | B7: TOTAL-BBSI.JO | C7: 10 | E7: =E6+C7-D7 -> 603 | F7: COCOK
A8: 43374 | B8: INDONAKANO-SEIWA | C8: 12 | E8: =E7+C8-D8 -> 615
A9: 43374 | B9: BCP-AHM 103+66 | C9: 169 | E9: =E8+C9-D9 -> 784 | F9: COCOK
A10: 43435 | B10: TBP-RS.GRAHA | C10: 40 | E10: =E9+C10-D10 -> 824
A11: 43435 | B11: BHINEKA-AHM | C11: 10 | E11: =E10+C11-D11 -> 834
A12: 13/1/2018 | B12: BHINEKA-AHM 4+47 | C12: 51 | E12: =E11+C12-D12 -> 885
A13: 15/1/2018 | B13: BHINEKA-AHM | C13: 1 | E13: =E12+C13-D13 -> 886
A14: 16/1/2018 | B14: INDONAKANO-HIRUTA | C14: 4 | E14: =E13+C14-D14 -> 890
A15: 17/1/2018 | B15: JKA-JOB GDNG | C15: 4 | E15: =E14+C15-D15 -> 894
A16: 18/1/2018 | B16: INDONAKANO-THAI SUMMIT | C16: 10 | E16: =E15+C16-D16 -> 904
A17: 22/1/2018 | B17: TBP-BBSI.JO | C17: 22 | E17: =E16+C17-D17 -> 926
A18: 22/1/2018 | B18: NKE-CHADSTONE | C18: 15 | E18: =E17+C18-D18 -> 941
A19: 23/1/2018 | B19: TBP-APARTEMEN AERIUM | D19: 60 | E19: =E18+C19-D19 -> 881
A20: 24/1/2018 | B20: INDONAKANO-HIRUTA 19+6 | C20: 25 | E20: =E19+C20-D20 -> 906
A21: 24/1/2018 | B21: BHINEKA-AHM | D21: 100 | E21: =E20+C21-D21 -> 806
A22: 25/1/2018 | B22: TBP-PAKUBUWONO | C22: 3 | E22: =E21+C22-D22 -> 809
A23: 25/1/2018 | B23: INDONAKANO-SEIWA | D23: 8 | E23: =E22+C23-D23 -> 801
A24: 26/1/2018 | B24: TBP-LAVIE | C24: 6 | E24: =E23+C24-D24 -> 807
A25: 26/1/2018 | B25: INTERDESIGN-LRT PALEMBANG | D25: 48 | E25: =E24+C25-D25 -> 759
A26: 28/1/2018 | B26: INDONAKANO-PANASONIC GOBEL | C26: 3 | E26: =E25+C26-D26 -> 762
A27: 31/1/2018 | B27: TBP-PAKUBUWONO | C27: 7 | E27: =E26+C27-D27 -> 769
A28: 43222 | B28: INDONAKANO-THAI SUMMIT | C28: 9 | E28: =E27+C28-D28 -> 778
A29: 43222 | B29: INDONAKANO-YAMADA | C29: 35 | E29: =E28+C29-D29 -> 813
A30: 43283 | B30: NINDYA KARYA-VENUE LAYAR | D30: 12 | E30: =E29+C30-D30 -> 801
A31: 43314 | B31: INDONAKANO-HIRUTA | C31: 2 | E31: =E30+C31-D31 -> 803
A32: 43345 | B32: TBP-BBSI.JO | C32: 13 | E32: =E31+C32-D32 -> 816
A33: 13/2/2018 | B33: INDONAKANO-HIRUTA | C33: 7 | E33: =E32+C33-D33 -> 823
A34: 15/2/2018 | B34: TBP-BEJ | D34: 20 | E34: =E33+C34-D34 -> 803
A35: 17/2/2018 | B35: TBP-VERDE KUNINGAN | C35: 4 | E35: =E34+C35-D35 -> 807
A36: 17/2/2018 | B36: INDONAKANO-TERAOKA-KARAWANG | D36: 4 | E36: =E35+C36-D36 -> 803
A37: 22/2/2018 | B37: TBP-APT.AERIUM | C37: 30 | E37: =E36+C37-D37 -> 833
A38: 22/2/2018 | B38: WIKA-TRANS CIBUBUR | D38: 50 | E38: =E37+C38-D38 -> 783
A39: 23/2/2018 | B39: INDONAKANO-SEIWA | D39: 18 | E39: =E38+C39-D39 -> 765
A40: 23/2/2018 | B40: NINDYA KARYA-VENUE LAYAR | D40: 18 | E40: =E39+C40-D40 -> 747
A41: 43103 | B41: BHINEKA-AHM | C41: 30 | E41: =E40+C41-D41 -> 777
A42: 43223 | B42: TBP-PAKUBUWONO | C42: 1 | E42: =E41+C42-D42 -> 778
...

Sheet CAT WALK
A1: NAMA BARANG : CAT WALK
A3: TGL | B3: NAMA PT-PROYEK | C3: MASUK | D3: KELUAR | E3: SISA | F3: KETERANGAN | G3: STOK GUDANG (WARDI)
B4: SISA STOK 2017 | E4: 990
A5: 43132 | B5: TBP-LAVIE | C5: 52 | E5: =E4+C5-D5 -> 1042
A6: 43132 | B6: TBP-BBSI.JO | C6: 19 | E6: =E5+C6-D6 -> 1061
A7: 43160 | B7: TBP-BBSI.JO | C7: 162 | E7: =E6+C7-D7 -> 1223 | F7: COCOK
A8: 43191 | B8: TBP-BBSI.JO | C8: 27 | E8: =E7+C8-D8 -> 1250 | F8: COCOK
A9: 43221 | B9: TBP-LAVIE | C9: 7 | E9: =E8+C9-D9 -> 1257 | F9: COCOK
A10: 43252 | B10: TOTAL-BBSI.JO | C10: 168 | E10: =E9+C10-D10 -> 1425 | F10: COCOK
A11: 43344 | B11: TOTAL-BBSI.JO | C11: 39 | E11: =E10+C11-D11 -> 1464 | F11: COCOK
A12: 43374 | B12: INDONAKANO-SEIWA | C12: 26 | E12: =E11+C12-D12 -> 1490
A13: 43374 | B13: ACSET-VISTA | C13: 63 | E13: =E12+C13-D13 -> 1553 | F13: COCOK
A14: 43405 | B14: TOTAL-BBSI.JO | C14: 20 | E14: =E13+C14-D14 -> 1573
A15: 43405 | B15: TOTAL-BBSI.JO | C15: 14 | E15: =E14+C15-D15 -> 1587
A16: 43405 | B16: POLABAJA-TREEPARK | C16: 11 | E16: =E15+C16-D16 -> 1598
A17: 43435 | B17: TBP-RS.GRAHA 37+8 | C17: 45 | E17: =E16+C17-D17 -> 1643
A18: 43435 | B18: INDONAKANO-THAI SUMMIT | C18: 162 | E18: =E17+C18-D18 -> 1805 | F18: COCOK
A19: 43435 | B19: TOTAL-THAMRIN | D19: 162 | E19: =E18+C19-D19 -> 1643
A20: 13/1/2018 | B20: TBP-LAVIE | C20: 11 | E20: =E19+C20-D20 -> 1654
A21: 13/1/2018 | B21: TOTAL-BBSI.JO | C21: 45 | E21: =E20+C21-D21 -> 1699
A22: 13/1/2018 | B22: TOTAL-THAMRIN 161+164+166 | D22: 491 | E22: =E21+C22-D22 -> 1208
A23: 15/1/2018 | B23: BHINEKA-AHM | C23: 13 | E23: =E22+C23-D23 -> 1221
A24: 15/1/2018 | B24: TBP-THAMRIN 9 | D24: 163 | E24: =E23+C24-D24 -> 1058
A25: 16/1/2018 | B25: TBP-BBSI.JO | C25: 86 | E25: =E24+C25-D25 -> 1144
A26: 16/1/2018 | B26: INDONAKANO-HIRUTA | C26: 81 | E26: =E25+C26-D26 -> 1225
A27: 16/1/2018 | B27: INDONAKANO-THAI SUMMIT | C27: 77 | E27: =E26+C27-D27 -> 1302 | F27: COCOK
A28: 17/1/2018 | B28: JKA-JOB GDNG | C28: 11 | E28: =E27+C28-D28 -> 1313
A29: 18/1/2018 | B29: INDONAKANO-THAI SUMMIT | C29: 23 | E29: =E28+C29-D29 -> 1336
A30: 18/1/2018 | B30: TBP-LAVIE 24+10 | C30: 34 | E30: =E29+C30-D30 -> 1370
A31: 19/1/2018 | B31: TBP-THAMRIN 9 . 166+34 | D31: 200 | E31: =E30+C31-D31 -> 1170 | F31: COCOK
A32: 20/1/2018 | B32: TBP-LAVIE | C32: 53 | E32: =E31+C32-D32 -> 1223 | F32: COCOK
A33: 22/1/2018 | B33: TBP-LAVIE | C33: 30 | E33: =E32+C33-D33 -> 1253
A34: 22/1/2018 | B34: TOTAL-BBSI.JO | C34: 90 | E34: =E33+C34-D34 -> 1343
A35: 23/1/2018 | B35: TBP-LAVIE | C35: 50 | E35: =E34+C35-D35 -> 1393
A36: 23/1/2018 | B36: ACSET-WEST VISTA | C36: 30 | E36: =E35+C36-D36 -> 1423
A37: 23/1/2018 | B37: TBP-APARTEMEN AERIUM | D37: 60 | E37: =E36+C37-D37 -> 1363
A38: 23/1/2018 | B38: BCP-AHM | D38: 561 | E38: =E37+C38-D38 -> 802 | F38: COCOK
A39: 24/1/2018 | B39: INDONAKANO-HIRUTA | C39: 27 | E39: =E38+C39-D39 -> 829
A40: 24/1/2018 | B40: BHINEKA-AHM | D40: 139 | E40: =E39+C40-D40 -> 690 | F40: COCOK | G40: 493 | H40: =E40-G40 -> 197
A41: 25/1/2018 | B41: TBP-LAVIE | C41: 13 | E41: =E40+C41-D41 -> 703 | G41: =G40+C41-D41 -> 506
...

Sheet PIPA SUPORT
A2: NAMA BARANG : PIPA SUPORT
A4: TGL | B4: NAMA PT-PROYEK | C4: MASUK | D4: KELUAR | E4: SISA | F4: KETERANGAN
B5: SISA STOK 2017 | E5: 822
A6: 43221 | B6: NINDYA.LTM KSO-PUSK.CEGER | C6: 7 | E6: =E5+C6-D6 -> 829
A7: 43221 | B7: NINDYA KARYA-SDN 04 MERUYA | C7: 52 | E7: =E6+C7-D7 -> 881 | F7: COCOK
A8: 43313 | B8: NINDYA.LTM KSO-PUSK.CILILITAN | C8: 11 | E8: =E7+C8-D8 -> 892
A9: 43313 | B9: INDONAKANO-PANASONIC GOBEL | C9: 19 | E9: =E8+C9-D9 -> 911 | F9: COCOK
A10: 43374 | B10: ACSET-VISTA | C10: 6 | E10: =E9+C10-D10 -> 917
A11: 43374 | B11: NINDYA KARYA-PUSK.CMPK PUTIH | C11: 3 | E11: =E10+C11-D11 -> 920 | F11: COCOK
A12: 43405 | B12: NINDYA KARYA-SDN KEB.JERUK 06 | C12: 4 | E12: =E11+C12-D12 -> 924
A13: 43405 | B13: BHINEKA-AHM | C13: 110 | E13: =E12+C13-D13 -> 1034
A14: 43435 | B14: BHINEKA-AHM | C14: 91 | E14: =E13+C14-D14 -> 1125 | F14: COCOK
A15: 13/1/2018 | B15: BHINEKA-AHM | C15: 41 | E15: =E14+C15-D15 -> 1166
A16: 15/1/2018 | B16: NINDYA-LTM KSO-JOHAR BARU | C16: 11 | E16: =E15+C16-D16 -> 1177
A17: 16/1/2018 | B17: NINDYA KARYA-SDN 04 MERUYA | C17: 1 | E17: =E16+C17-D17 -> 1178 | F17: COCOK
A18: 17/1/2018 | B18: NINDYA LTM KSO-PUSK.CILILITAN | C18: 2 | E18: =E17+C18-D18 -> 1180
A19: 19/1/2018 | B19: WIKA-GEDUNG | C19: 75 | E19: =E18+C19-D19 -> 1255
A20: 19/1/2018 | B20: ACSET-TOTO (CIKOKOL) | C20: 42 | E20: =E19+C20-D20 -> 1297
A21: 21/1/2017 | B21: IDEA MANDIRI | C21: 35 | E21: =E20+C21-D21 -> 1332
A22: 23/1/2018 | B22: ACSET-WEST VISTA | C22: 21 | E22: =E21+C22-D22 -> 1353
A23: 26/1/2018 | B23: INDONAKANO-PANASONIC GOBEL | C23: 3 | E23: =E22+C23-D23 -> 1356
A24: 26/1/2018 | B24: NINDYA KARYA-VANUE LAYAR | D24: 100 | E24: =E23+C24-D24 -> 1256
A25: 43102 | B25: NINDYA-LTM KSO | C25: 42 | E25: =E24+C25-D25 -> 1298
A26: 43222 | B26: INDONAKANO-THAISUMIT | C26: 3 | E26: =E25+C26-D26 -> 1301
A27: 43222 | B27: INDONAKANO-YAMADA | C27: 45 | E27: =E26+C27-D27 -> 1346
A28: 43222 | B28: NINDYA -KTM KSO MENTENG | C28: 11 | E28: =E27+C28-D28 -> 1357
A29: 43283 | B29: NINDYA-LTM KSO-PUSK.CEMPAKA PTH | C29: 1 | E29: =E28+C29-D29 -> 1358
A30: 43314 | B30: NINDYA-LTM KSO-PUSK.MANGGARAI | C30: 31 | E30: =E29+C30-D30 -> 1389
A31: 43324 | B31: NINDYA KARYA-HARKIT | C31: 38 | E31: =E30+C31-D31 -> 1427
A32: 14/2/2018 | B32: NINDYA-LTM KSO-BIDARA CINA | C32: 10 | E32: =E31+C32-D32 -> 1437
A33: 17/2/2018 | B33: WIKA-TRANS CIBUBUR | D33: 100 | E33: =E32+C33-D33 -> 1337
A34: 18/2/2018 | B34: WIKA-TRANS CIBUBUR | D34: 300 | E34: =E33+C34-D34 -> 1037
A35: 19/2/2018 | B35: NINDYA KARYA-HARKIT | C35: 5 | E35: =E34+C35-D35 -> 1042
A36: 20/2/2018 | B36: POLABAJA-INDRAMAYU | C36: 1 | E36: =E35+C36-D36 -> 1043
A37: 22/2/2018 | B37: TBP-LAVIE | C37: 24 | E37: =E36+C37-D37 -> 1067
A38: 22/2/2018 | B38: NINDYA-LTM KSO PUSK.MANGGARAI | C38: 70 | E38: =E37+C38-D38 -> 1137
A39: 27/2/2018 | B39: NINDYA-LTM KSO-PUSK.GDG.X-DERES | C39: 22 | E39: =E38+C39-D39 -> 1159
A40: 13/3/2018 | B40: BHINEKA-AHM | C40: 144 | E40: =E39+C40-D40 -> 1303
A41: 19/3/2018 | B41: IDEA MANDIRI-WOLTER | C41: 5 | E41: =E40+C41-D41 -> 1308
A42: 22/3/2018 | B42: ACSET-MCC | C42: 6 | E42: =E41+C42-D42 -> 1314 | F42: COCOK
...

Sheet SWIVEL CLAMP
A1: NAMA BARANG : SWIVLE CLAMP
A3: TGL | B3: NAMA PT-PROYEK | C3: MASUK | D3: KELUAR | E3: SISA | F3: KETERANGAN
B4: SISA ALAT 2017 | E4: 17613
A5: 43160 | B5: INDONAKANO-PANASONIC GOBEL | C5: 250 | E5: =E4+C5-D5 -> 17863 | F5: COCOK
A6: 43221 | B6: BHINEKA-AHM | C6: 4 | E6: =E5+C6-D6 -> 17867 | F6: COCOK
A7: 43252 | B7: ACSET-LRT CAWANG | D7: 400 | E7: =E6+C7-D7 -> 17467
A8: 43252 | B8: RENDEZ | C8: 200 | E8: =E7+C8-D8 -> 17667
A9: 43313 | B9: RENDEZ | C9: 100 | E9: =E8+C9-D9 -> 17767
A10: 43313 | B10: RENDEZ | D10: 100 | E10: =E9+C10-D10 -> 17667 | F10: COCOK
A11: 43313 | B11: INDONAKANO-SEIWA | C11: 500 | E11: =E10+C11-D11 -> 18167 | F11: COCOK
A12: 43313 | B12: INDONAKANO-THAISUMMIT | C12: 150 | E12: =E11+C12-D12 -> 18317
A13: 43374 | B13: INDONAKANO-SEIWA | C13: 400 | E13: =E12+C13-D13 -> 18717 | F13: COCOK
A14: 43405 | B14: NINDYA KARYA-SLIPI | D14: 100 | E14: =E13+C14-D14 -> 18617 | F14: COCOK
A15: 13/1/2018 | B15: BHINEKA-AHM 79+11 | C15: 1 | E15: =E14+C15-D15 -> 18618
A16: 13/1/2018 | B16: TBP-LAVIE | C16: 150 | E16: =E15+C16-D16 -> 18768
A17: 16/1/2018 | B17: INDONAKANO-HIRUTA | C17: 67 | E17: =E16+C17-D17 -> 18835
A18: 16/1/2018 | B18: INDONAKANO-THAI SUMMIT | C18: 120 | E18: =E17+C18-D18 -> 18955 | F18: COCOK
A19: 17/1/2018 | B19: TBP-PAKUBUWONO | D19: 111 | E19: =E18+C19-D19 -> 18844
A20: 18/1/2018 | B20: INDONAKANO-THAI SUMMIT | C20: 73 | E20: =E19+C20-D20 -> 18917
A21: 18/1/2018 | B21: TBP-LAVIE 50+1 | C21: 51 | E21: =E20+C21-D21 -> 18968 | F21: COCOK
A22: 22/1/2018 | B22: ACSET-LRT CAWANG | D22: 500 | E22: =E21+C22-D22 -> 18468
A23: 22/1/2018 | B23: RENDEZ | C23: 500 | E23: =E22+C23-D23 -> 18968
A24: 23/1/2018 | B24: TBP-LAVIE | C24: 100 | E24: =E23+C24-D24 -> 19068 | F24: COCOK
A25: 24/1/2018 | B25: INDONAKANO-HIRUTA 80+50 | C25: 130 | E25: =E24+C25-D25 -> 19198 | F25: COCOK
A26: 25/1/2018 | B26: INDONAKANO-SEIWA | D26: 50 | E26: =E25+C26-D26 -> 19148
A27: 26/1/2018 | B27: TBP-LAVIE 400+100 | C27: 500 | E27: =E26+C27-D27 -> 19648
A28: 26/1/2018 | B28: INDONAKANO-PANASONIC GOBEL | C28: 950 | E28: =E27+C28-D28 -> 20598
A29: 26/1/2018 | B29: INTERDESIGN-LRT PALEMBANG | D29: 288 | E29: =E28+C29-D29 -> 20310
A30: 28/1/2018 | B30: INDONAKANO-PANASONIC GOBEL | C30: 20 | E30: =E29+C30-D30 -> 20330
A31: 29/1/2018 | B31: NINDYA KARYA-HARAPAN KITA | C31: 63 | E31: =E30+C31-D31 -> 20393
A32: 31/1/2018 | B32: NINDYA KARYA-HARKIT | C32: 70 | E32: =E31+C32-D32 -> 20463
A33: 43133 | B33: INDONAKANO-THAI SUMMIT | C33: 179 | E33: =E32+C33-D33 -> 20642
A34: 43222 | B34: NINDYA KARYA-HARKIT | C34: 6 | E34: =E33+C34-D34 -> 20648
A35: 43222 | B35: INDONAKANO-YAMADA | C35: 182 | E35: =E34+C35-D35 -> 20830
A36: 43314 | B36: INDONAKANO-HIRUTA | C36: 210 | E36: =E35+C36-D36 -> 21040
A37: 43324 | B37: NINDYA KARYA-HARKIT | C37: 15 | E37: =E36+C37-D37 -> 21055
A38: 13/2/2018 | B38: INTERDESIGN-HOTEL SULTAN | C38: 8 | E38: =E37+C38-D38 -> 21063
A39: 13/2/2018 | B39: INDONAKANO-HIRUTA | C39: 450 | E39: =E38+C39-D39 -> 21513
A40: 15/2/2018 | B40: TBP-BEJ | D40: 300 | E40: =E39+C40-D40 -> 21213
A41: 17/2/2018 | B41: INDONAKANO-TERAOKA-KARAWANG | D41: 50 | E41: =E40+C41-D41 -> 21163
...

Sheet PIPE 1 M
B1: NAMA BARANG : PIPE 1 M
A3: TGL | B3: NAMA PT-PROYEK | C3: MASUK | D3: KELUAR | E3: SISA | F3: KETERANGAN
B4: SISA STOK 2017 | E4: 406
A5: 26/1/2018 | B5: TBP-LAVIE 40+4 | C5: 44 | E5: =E4+C5-D5 -> 450
A6: 43222 | B6: TBP-LAVIE | C6: 44 | E6: =E5+C6-D6 -> 494
A7: 22/2/2018 | B7: TBP-LAVIE | C7: 15 | E7: =E6+C7-D7 -> 509
A8: 26/2/2018 | B8: TBP-LAVIE | C8: 24 | E8: =E7+C8-D8 -> 533
A9: 16/3/2018 | B9: TBP-LAVIE | C9: 40 | E9: =E8+C9-D9 -> 573
A10: 28/3/2018 | B10: INDONAKANO-YAMADA | C10: 100 | E10: =E9+C10-D10 -> 673
A11: 43408 | B11: TBP-LAVIE | C11: 75 | E11: =E10+C11-D11 -> 748 | F11: COCOK
A12: 13/4/2018 | B12: TBP-LAVIE | C12: 10 | E12: =E11+C12-D12 -> 758 | F12: COCOK
A13: 24/4/2018 | B13: TBP-LAVIE | C13: 90 | E13: =E12+C13-D13 -> 848 | F13: COCOK
A14: 27/4/2018 | B14: TBP-LAVIE | C14: 125 | E14: =E13+C14-D14 -> 973 | F14: COCOK
A15: 14/5/2018 | B15: TBP-LAVIE | C15: 15 | E15: =E14+C15-D15 -> 988
A16: 19/5/2018 | B16: TBP-LEVIE | C16: 30 | E16: =E15+C16-D16 -> 1018 | F16: COCOK

Sheet PIPE 2 M
A1: NAMA BARANG : PIPE 2 M
A3: TGL | B3: NAMA PT-PROYEK | C3: MASUK | D3: KELUAR | E3: SISA | F3: KETERANGAN
B4: SISA STOK 2017 | E4: 1850
A5: 43221 | B5: BHINEKA-AHM | C5: 100 | E5: =E4+C5-D5 -> 1950
A6: 43313 | B6: INDONAKANO-PANASONIC GOBEL | C6: 36 | E6: =E5+C6-D6 -> 1986
A7: 13/1/2018 | B7: BHINEKA-AHM | C7: 131 | E7: =E6+C7-D7 -> 2117
A8: 24/1/2018 | B8: INDONAKANO-HIRUTA | C8: 28 | E8: =E7+C8-D8 -> 2145
A9: 26/1/2018 | B9: INDONAKANO-PANASONIC GOBEL | C9: 160 | E9: =E8+C9-D9 -> 2305
A10: 28/1/2018 | B10: INDONAKANO-PANASONIC GOBEL | C10: 34 | E10: =E9+C10-D10 -> 2339
A11: 43283 | B11: INDONAKANO-HIRUTA | C11: 36 | E11: =E10+C11-D11 -> 2375
A12: 13/2/2018 | B12: INDONAKANO-HIRUTA | C12: 34 | E12: =E11+C12-D12 -> 2409
A13: 23/2/2018 | B13: INDONAKANO-PANASONIC | C13: 80 | E13: =E12+C13-D13 -> 2489
A14: 43223 | B14: INDONAKANO-HIRUTA | C14: 33 | E14: =E13+C14-D14 -> 2522
A15: 43284 | B15: BCP-AHM | C15: 50 | E15: =E14+C15-D15 -> 2572
A16: 43315 | B16: INDONAKANO-THAI SUMMIT | C16: 7 | E16: =E15+C16-D16 -> 2579
A17: 43437 | B17: INDONAKANO-PANASONIC GOBEL | C17: 23 | E17: =E16+C17-D17 -> 2602
A18: 13/3/2018 | B18: BHINEKA-AHM | C18: 90 | E18: =E17+C18-D18 -> 2692 | F18: COCOK
A19: 14/3/2018 | B19: INDONAKANO-HIRUTA | C19: 9 | E19: =E18+C19-D19 -> 2701 | F19: COCOK
A20: 21/3/2018 | B20: INDONAKANO-PANASONIC GOBEL | C20: 100 | E20: =E19+C20-D20 -> 2801 | F20: COCOK
A21: 28/3/2018 | B21: INDONAKANO-YAMADA | C21: 13 | E21: =E20+C21-D21 -> 2814 | F21: COCOK
A22: 43135 | B22: INDONAKANO-PANASONIC GOBEL | C22: 63 | E22: =E21+C22-D22 -> 2877
A23: 43376 | B23: BCP-AHM | C23: 47 | E23: =E22+C23-D23 -> 2924 | F23: COCOK
A24: 24/4/2018 | B24: TAKENAKA-ASAHIMAS | D24: 200 | E24: =E23+C24-D24 -> 2724 | F24: COCOK
A25: 15/5/2018 | B25: INDONAKANO-AKS | D25: 20 | E25: =E24+C25-D25 -> 2704
A26: 25/5/2018 | B26: PT.SOVIN-ROBINA TOWER-GATOT | D26: 25 | E26: =E25+C26-D26 -> 2679 | F26: COCOK
A27: 43165 | B27: BPK HAJI | D27: 5 | E27: =E26+C27-D27 -> 2674 | F27: COCOK

Sheet PIPE 3 M
B2: NAMA BARANG : PIPE 3 M
B4: TGL | C4: NAMA PT-PROYEK | D4: MASUK | E4: KELUAR | F4: SISA | G4: KETERANGAN
C5: SISA STOK 2017 | F5: 120
B6: 43191 | C6: BHINEKA-AHM | D6: 400 | F6: =F5+D6-E6 -> 520 | G6: COCOK
B7: 43221 | C7: BHINEKA-AHM | D7: 175 | F7: =F6+D7-E7 -> 695
B8: 43313 | C8: INDONAKANO-PANASONIC | D8: 1 | F8: =F7+D8-E8 -> 696 | G8: COCOK
B9: 43405 | C9: TOTAL-BBSI.JO | D9: 43 | F9: =F8+D9-E9 -> 739
B10: 43435 | C10: BHINEKA-AHM | D10: 429 | F10: =F9+D10-E10 -> 1168 | G10: COCOK
B11: 13/1/2018 | C11: BHINEKA-AHM | D11: 21 | F11: =F10+D11-E11 -> 1189
B12: 13/1/2018 | C12: TBP-LAVIE | D12: 90 | F12: =F11+D12-E12 -> 1279 | G12: COCOK
B13: 18/1/2018 | C13: INDONAKANO-THAI SUMMIT | D13: 49 | F13: =F12+D13-E13 -> 1328
B14: 19/1/2018 | C14: ACSET-TOTO (CIKOKOL) | D14: 21 | F14: =F13+D14-E14 -> 1349 | G14: COCOK
B15: 24/1/2018 | C15: INDONAKANO-HIRUTA | D15: 6 | F15: =F14+D15-E15 -> 1355 | G15: COCOK
B16: 26/1/2018 | C16: TBP-LAVIE 71+38 | D16: 109 | F16: =F15+D16-E16 -> 1464
B17: 26/1/2018 | C17: INTERDESIGN-LRT PALEMBANG | E17: 144 | F17: =F16+D17-E17 -> 1320 | G17: COCOK
B18: 28/1/2018 | C18: INDONAKANO-PANASONIC GOBEL | D18: 49 | F18: =F17+D18-E18 -> 1369
B19: 29/1/2018 | C19: NINDYA KARYA-HARAPAN KITA | D19: 6 | F19: =F18+D19-E19 -> 1375 | G19: COCOK
B20: 31/1/2018 | C20: TBP-PAKUBUWONO | D20: 5 | F20: =F19+D20-E20 -> 1380
B21: 43222 | C21: TBP-LAVIE | D21: 70 | F21: =F20+D21-E21 -> 1450
B22: 43222 | C22: INDONAKANO-THAISUMIT | D22: 25 | F22: =F21+D22-E22 -> 1475
B23: 43283 | C23: TBP-PAKUBUWONO | D23: 8 | F23: =F22+D23-E23 -> 1483
B24: 43283 | C24: INDONAKANO-HIRUTA | D24: 22 | F24: =F23+D24-E24 -> 1505
B25: 43314 | C25: NINDYA KARYA-HARAPAN KITA | D25: 3 | F25: =F24+D25-E25 -> 1508
B26: 13/2/2018 | C26: INDONAKANO-HIRUTA | D26: 17 | F26: =F25+D26-E26 -> 1525
B27: 14/2/2018 | C27: TBP-LAVIE | D27: 37 | F27: =F26+D27-E27 -> 1562
B28: 15/2/2018 | C28: TBP-BEJ | E28: 20 | F28: =F27+D28-E28 -> 1542
B29: 20/2/2018 | C29: TBP-LAVIE 45+47 | D29: 92 | F29: =F28+D29-E29 -> 1634
B30: 22/2/2018 | C30: TBP-LAVIE | D30: 11 | F30: =F29+D30-E30 -> 1645
B31: 23/2/2018 | C31: INDONAKANO-SEIWA | E31: 50 | F31: =F30+D31-E31 -> 1595
B32: 23/2/2018 | C32: PANASONIC-GOBEL | D32: 14 | F32: =F31+D32-E32 -> 1609
B33: 24/2/2018 | C33: TBP-VERDE 2 | D33: 494 | F33: =F32+D33-E33 -> 2103
B34: 43134 | C34: TBP-BURSA EFEK-SUDIRMAN | E34: 100 | F34: =F33+D34-E34 -> 2003
B35: 43223 | C35: INDONAKANO-HIRUTA | D35: 34 | F35: =F34+D35-E35 -> 2037
B36: 43223 | C36: TBP-PAKUBUWONO | D36: 3 | F36: =F35+D36-E36 -> 2040
B37: 43284 | C37: BCP-AHM | D37: 50 | F37: =F36+D37-E37 -> 2090
B38: 43315 | C38: INDONAKANO-THAI SUMMIT | D38: 14 | F38: =F37+D38-E38 -> 2104
B39: 43346 | C39: TBP-VERDE 2 | D39: 264 | F39: =F38+D39-E39 -> 2368
B40: 43437 | C40: INDONAKANO-PANASONIC GOBEL | D40: 42 | F40: =F39+D40-E40 -> 2410
B41: 13/3/2018 | C41: TBP-PAKUBUWONO | D41: 1 | F41: =F40+D41-E41 -> 2411
B42: 13/3/2018 | C42: BHINEKA-AHM | D42: 119 | F42: =F41+D42-E42 -> 2530
...

Sheet PIPE 4 M
A1: NAMA BARANG : PIPE 4 M
A3: TGL | B3: NAMA PT-PROYEK | C3: MASUK | D3: KELUAR | E3: SISA | F3: KETERANGAN
B4: Sisa stok 2016 | E4: 162
A5: 43191 | B5: BHINEKA-AHM | C5: 100 | E5: =E4+C5-D5 -> 262
A6: 43221 | B6: BHINEKA-AHM | C6: 81 | E6: =E5+C6-D6 -> 343
A7: 43313 | B7: INDONAKANO-PANASONIC GOBEL | C7: 2 | E7: =E6+C7-D7 -> 345
A8: 43374 | B8: INDONAKANO-SEIWA | C8: 26 | E8: =E7+C8-D8 -> 371
A9: 43435 | B9: BHINEKA-AHM | C9: 99 | E9: =E8+C9-D9 -> 470
A10: 13/1/2018 | B10: BHINEKA-AHM | C10: 12 | E10: =E9+C10-D10 -> 482
A11: 13/1/2018 | B11: TBP-LAVIE | C11: 13 | E11: =E10+C11-D11 -> 495
A12: 15/1/2018 | B12: BHINEKA-AHM | C12: 2 | E12: =E11+C12-D12 -> 497
A13: 24/1/2018 | B13: INDONAKANO-HIRUTA | C13: 4 | E13: =E12+C13-D13 -> 501
A14: 28/1/2018 | B14: INDONAKANO-PANASONIC GOBEL | C14: 19 | E14: =E13+C14-D14 -> 520
A15: 43283 | B15: INDONAKANO-HIRUTA | C15: 26 | E15: =E14+C15-D15 -> 546
A16: 13/2/2018 | B16: INDONAKANO-HIRUTA | C16: 30 | E16: =E15+C16-D16 -> 576
A17: 20/2/2018 | B17: TBP-LAVIE | C17: 1 | E17: =E16+C17-D17 -> 577
A18: 23/2/2018 | B18: INDONAKANO-PANASONIC GOBEL | C18: 27 | E18: =E17+C18-D18 -> 604
A19: 23/2/2018 | B19: INDONAKANO-SEIWA | D19: 35 | E19: =E18+C19-D19 -> 569
A20: 43223 | B20: INDONAKANO-HIRUTA | C20: 7 | E20: =E19+C20-D20 -> 576
A21: 43284 | B21: BCP-AHM | C21: 50 | E21: =E20+C21-D21 -> 626
A22: 43284 | B22: WIKA - TAMAN SARI | D22: 100 | E22: =E21+C22-D22 -> 526
A23: 43437 | B23: INDONAKANO-PANASONIC GOBEL | C23: 32 | E23: =E22+C23-D23 -> 558
A24: 13/3/2018 | B24: BHINEKA-AHM | C24: 198 | E24: =E23+C24-D24 -> 756 | F24: COCOK
A25: 14/3/2018 | B25: INDONAKANO-HIRUTA | C25: 14 | E25: =E24+C25-D25 -> 770
A26: 14/3/2018 | B26: INDONAKANO-SEIWA | D26: 20 | E26: =E25+C26-D26 -> 750
A27: 21/3/2018 | B27: INDONAKANO-PANASONIC GOBEL | C27: 21 | E27: =E26+C27-D27 -> 771
A28: 28/3/2018 | B28: INDONAKANO-SEIWA | C28: 74 | E28: =E27+C28-D28 -> 845
A29: 43135 | B29: INDONAKANO-PANASONIC GOBEL | C29: 14 | E29: =E28+C29-D29 -> 859
A30: 43376 | B30: BCP-AHM | C30: 33 | E30: =E29+C30-D30 -> 892 | F30: COCOK
A31: 24/4/2018 | B31: TAKENAKA-ASAHIMAS | D31: 200 | E31: =E30+C31-D31 -> 692 | F31: COCOK
A32: 27/4/2018 | B32: INDONAKANO-PANASONIC | C32: 6 | E32: =E31+C32-D32 -> 698 | F32: COCOK
A33: 19/5/2018 | B33: TBP-LEVIE | C33: 20 | E33: =E32+C33-D33 -> 718
A34: 23/5/2018 | B34: TBP-LAVIE | C34: 2 | E34: =E33+C34-D34 -> 720 | F34: COCOK
A35: 26/5/2018 | B35: TBP-LAVIE | C35: 9 | E35: =E34+C35-D35 -> 729 | F35: COCOK
A36: 43137 | B36: TBP-LAVIE | C36: 12 | E36: =E35+C36-D36 -> 741 | F36: COCOK

Sheet PIPE 5 M
A2: NAMA BARANG : PIPE 5 M
A4: TGL | B4: NAMA PT-PROYEK | C4: MASUK | D4: KELUAR | E4: SISA | F4: KETERANGAN
B5: SISA STOK | E5: 0

Sheet PIPE 6 M
A2: NAMA BARANG : PIPE 6 M (GALVANIS/HITAM)
A4: TGL | B4: NAMA PT-PROYEK | C4: MASUK | D4: KELUAR | E4: SISA | F4: KETERANGAN
B5: SISA STOK 2017 | E5: 668
A6: 43313 | B6: INDONAKANO-PANASONIC GOBEL | C6: 98 | E6: =E5+C6-D6 -> 766
A7: 43344 | B7: NKE-NARGONDA | D7: 70 | E7: =E6+C7-D7 -> 696
A8: 43374 | B8: INDONAKANO-SEIWA | C8: 77 | E8: =E7+C8-D8 -> 773
A9: 43405 | B9: NINDYA KARYA-SLIPI | D9: 20 | E9: =E8+C9-D9 -> 753
A10: 43435 | B10: BHINEKA-AHM | C10: 40 | E10: =E9+C10-D10 -> 793
A11: 13/1/2018 | B11: BHINEKA-AHM | C11: 16 | E11: =E10+C11-D11 -> 809
A12: 18/1/2018 | B12: INDONAKANO-THAI SUMMIT | C12: 76 | E12: =E11+C12-D12 -> 885
A13: 19/1/2018 | B13: BAJAMARGA KARISMA | C13: 120 | E13: =E12+C13-D13 -> 1005
A14: 22/1/2018 | B14: TBP-APARTEMEN AERIUM TPB 120+40 | D14: 160 | E14: =E13+C14-D14 -> 845
A15: 24/1/2018 | B15: INDONAKANO-HIRUTA | C15: 8 | E15: =E14+C15-D15 -> 853
A16: 24/1/2018 | B16: NINDYA KARYA-RS.HARKIT | C16: 6 | E16: =E15+C16-D16 -> 859
A17: 28/1/2018 | B17: INDONAKANO-PANASONIC GOBEL | C17: 165 | E17: =E16+C17-D17 -> 1024
A18: 29/1/2018 | B18: NINDYA KARYA-HARAPAN KITA | C18: 17 | E18: =E17+C18-D18 -> 1041
A19: 43133 | B19: INDONAKANO-THAI SUMMIT | C19: 38 | E19: =E18+C19-D19 -> 1079
A20: 43222 | B20: INDONAKANO-THAISUMIT | C20: 13 | E20: =E19+C20-D20 -> 1092
A21: 43222 | B21: INDONAKANO-YAMADA | C21: 81 | E21: =E20+C21-D21 -> 1173
A22: 43283 | B22: INDONAKANO-HIRUTA | C22: 78 | E22: =E21+C22-D22 -> 1251
A23: 13/2/2018 | B23: INDONAKANO-HIRUTA | C23: 116 | E23: =E22+C23-D23 -> 1367
A24: 15/2/2018 | B24: TBP-BEJ | D24: 80 | E24: =E23+C24-D24 -> 1287
A25: 17/2/2018 | B25: INDONAKANO-TERAOKA-KARAWANG | D25: 15 | E25: =E24+C25-D25 -> 1272
A26: 20/2/2018 | B26: JAGAT-JOB | C26: 50 | E26: =E25+C26-D26 -> 1322
A27: 20/2/2018 | B27: TBP-LAVIE 45+47 | C27: 34 | E27: =E26+C27-D27 -> 1356
A28: 22/2/2018 | B28: TBP-APT.AERIUM | C28: 31 | E28: =E27+C28-D28 -> 1387
A29: 23/2/2018 | B29: INDONAKANO-PANASONIC GOBEL | C29: 160 | E29: =E28+C29-D29 -> 1547
A30: 23/2/2018 | B30: INDONAKANO-SEIWA | D30: 75 | E30: =E29+C30-D30 -> 1472
A31: 24/2/2018 | B31: ACSET-ASTRA BIZ CENTRE BSD TANGGERANG | C31: 10 | E31: =E30+C31-D31 -> 1482
A32: 26/2/2018 | B32: NKE-WCT | C32: 240 | E32: =E31+C32-D32 -> 1722
A33: 43134 | B33: TBP-BURSA EFEK-SUDIRMAN | D33: 135 | E33: =E32+C33-D33 -> 1587
A34: 43223 | B34: INDONAKANO-HIRUTA | C34: 45 | E34: =E33+C34-D34 -> 1632
A35: 43315 | B35: INDONAKANO-THAI SUMMIT | C35: 13 | E35: =E34+C35-D35 -> 1645
A36: 43437 | B36: INDONAKANO-PANASONIC GOBEL | C36: 41 | E36: =E35+C36-D36 -> 1686
A37: 13/3/2018 | B37: BHINEKA-AHM | C37: 140 | E37: =E36+C37-D37 -> 1826 | F37: COCOK
A38: 14/3/2018 | B38: INDONAKANO-HIRUTA | C38: 12 | E38: =E37+C38-D38 -> 1838
A39: 14/3/2018 | B39: INDONAKANO-SEIWA | D39: 25 | E39: =E38+C39-D39 -> 1813
A40: 21/3/2018 | B40: INDONAKANO-PANASONIC GOBEL | C40: 47 | E40: =E39+C40-D40 -> 1860
A41: 23/3/2018 | B41: TBP-PAKUBUWONO | C41: 8 | E41: =E40+C41-D41 -> 1868
A42: 24/3/2018 | B42: TBP-LAVIE | C42: 50 | E42: =E41+C42-D42 -> 1918
...

Sheet HB
A2: NAMA BARANG : HORRY BEAM
A4: TGL | B4: NAMA PT-PROYEK | C4: MASUK | D4: KELUAR | E4: SISA | F4: KETERANGAN
B5: SISA ALAT 2017 | E5: 2088
A6: 21/1/2018 | B6: IDEA MANDIRI | C6: 74 | E6: =E5+C6-D6 -> 2162
A7: 27/3/2018 | B7: IDEA MANDIRI-SIMPRUG | D7: 100 | E7: =E6+C7-D7 -> 2062 | F7: COCOK
A8: 29/3/2018 | B8: IDEA MANDIRI-WOLTER | C8: 44 | E8: =E7+C8-D8 -> 2106 | F8: COCOK
A9: 17/4/2018 | B9: IDEA MANDIRI BLOK M | C9: 57 | E9: =E8+C9-D9 -> 2163 | F9: COCOK
A10: 24/4/2018 | B10: TBP-LAVIE | C10: 4 | E10: =E9+C10-D10 -> 2167 | F10: COCOK
A11: 15/5/2018 | B11: IDEA MANDIRI-SIMPRUG | C11: 84 | E11: =E10+C11-D11 -> 2251
A12: 15/5/2018 | B12: IDEA MANDIRI-KARAWANG | C12: 16 | E12: =E11+C12-D12 -> 2267 | F12: COCOK

Sheet RODA
A2: NAMA BARANG : RODA
A4: TGL | B4: NAMA PT-PROYEK | C4: MASUK | D4: KELUAR | E4: SISA | F4: KETERANGAN
B5: SISA ALAT 2017 | E5: 123
A6: 43135 | B6: DHARMA EKA-MENARA ASTRA | D6: 24 | E6: =E5+C6-D6 -> 99
A7: 15/5/2018 | B7: INDONAKANO-AKS | D7: 20 | E7: =E6+C7-D7 -> 79

Sheet UH 85
A1: NAMA BARANG UH 85
A3: TGL | B3: NAMA PT-PROYEK | C3: MASUK | D3: KELUAR | E3: SISA | F3: KETERANGAN
B4: SISA ALAT 2017 | E4: 2974
A5: 16/1/2017 | B5: INNOTECH SYSTEMS-THAMRIN 9 | C5: 63 | E5: =E4+C5-D5 -> 3037
A6: 19/1/2017 | B6: PMI-CIKOKOL | C6: 82 | E6: =E5+C6-D6 -> 3119
A7: 26/1/2018 | B7: INNOTECH SYSTEMS | C7: 10 | E7: =E6+C7-D7 -> 3129
A8: 15/2/2017 | B8: WIKA-GEDUNG TRANS CIBUBUR | D8: 300 | E8: =E7+C8-D8 -> 2829
A9: 17/2/2018 | B9: WIKA-TRANS CIBUBUR | D9: 300 | E9: =E8+C9-D9 -> 2529
A10: 18/2/2018 | B10: WIKA-TRANS CIBUBUR | D10: 200 | E10: =E9+C10-D10 -> 2329
A11: 19/2/2018 | B11: WIKA-TRANS CIBUBUR | D11: 250 | E11: =E10+C11-D11 -> 2079
